Workbook

Sheet כיתה ו1
D1: נושא | F1: מבנה עשרוני | G1: פעולות בשלמים | K1: פעולות בשלמים | L1: פעולות בשלמים | M1: פעולות בשלמים | N1: פעולות בשברים | R1: משמעות השבר | S1: חקר נתונים | W1: משמעות השבר | X1: מספרים עשרוניים | Y1: משמעות השבר | Z1: מספרים עשרוניים | AA1: פעולות בשברים | AB1: מצולעים | AC1: מצולעים | AD1: מדידות | AE1: מדידות
D2: שאלה | F2: 1 | G2: 2 | K2: 3 | L2: 4 | M2: 5 | N2: 6 | R2: 7 | S2: 8 | W2: 9 | X2: 10 | Y2: 11 | Z2: 12 | AA2: 13 | AB2: 14 | AC2: 15 | AD2: 16 | AE2: 17
D3: תת שאלה | F3: 1 | G3: 2א | H3: 2ב | I3: 2ג | J3: 2ד | K3: 3 | L3: 4 | M3: 5 | N3: 6א | O3: 6ב | P3: 6ג | Q3: 6ד | R3: 7 | S3: 8א | T3: 8ב | U3: 8ג | V3: 8ד | W3: 9 | X3: 10 | Y3: 11 | Z3: 12 | AA3: 13 | AB3: 14 | AC3: 15 | AD3: 16 | AE3: 17
D4: תת נושא | F4: כתיבת מספר | G4: סדר פעולות | H4: חיסור | I4: כפל דו בדו | J4: חילוק | K4: משוואה בחיבור ואי שיוויון | L4: אומדן בכפל | M4: התאמת תרגיל לשאלה מילולית | N4: חיבור | O4: חיבור | P4: חיסור | Q4: כפל כחיבור חוזר | R4: השוואת שברים | S4: קריאת דיאגרמה | T4: קריאת דיאגרמה | U4: קריאת דיאגרמה | V4: איזה חלק | W4: השבר כחלק מכמות | X4: מהות העשרוני | Y4: השבר על ישר מספרים | Z4: סדרות | AA4: שאלה מילולית | AB4: משפחת המרובעים | AC4: גובה במשולש | AD4: שטח משולש | AE4: שטחים מורכבים
D5: רמת חשיבה | F5: חשיבה אלגוריתמית | G5: חשיבה אלגוריתמית | H5: חשיבה אלגוריתמית | I5: חשיבה אלגוריתמית | J5: חשיבה אלגוריתמית | K5: חשיבה תהליכית | L5: חשיבה תהליכית | M5: חשיבה תהליכית | N5: חשיבה אלגוריתמית | O5: חשיבה אלגוריתמית | P5: חשיבה אלגוריתמית | Q5: חשיבה אלגוריתמית | R5: חשיבה תהליכית | S5: ידע וזיהוי | T5: ידע וזיהוי | U5: ידע וזיהוי | V5: חשיבה תהליכית | W5: ידע וזיהוי | X5: ידע וזיהוי | Y5: ידע וזיהוי | Z5: חשיבה אלגוריתמית | AA5: חשיבה תהליכית | AB5: ידע וזיהוי | AC5: ידע וזיהוי | AD5: חשיבה אלגוריתמית | AE5: חשיבה תהליכית
A6: מס' | B6: ת.ז התלמיד | C6: שם התלמיד | D6: שכבה | E6: כיתה | F6: ניקוד | G6: ניקוד | H6: ניקוד | I6: ניקוד | J6: ניקוד | K6: ניקוד | L6: ניקוד | M6: ניקוד | N6: ניקוד | O6: ניקוד | P6: ניקוד | Q6: ניקוד | R6: ניקוד | S6: ניקוד | T6: ניקוד | U6: ניקוד | V6: ניקוד | W6: ניקוד | X6: ניקוד | Y6: ניקוד | Z6: ניקוד | AA6: ניקוד | AB6: ניקוד | AC6: ניקוד | AD6: ניקוד | AE6: ניקוד | AF6: ציון מבחן
A7: 1 | D7: ו | E7: 1 | AF7: =SUM(F7:AE7) -> 0
A8: 2 | D8: ו | E8: 1 | AF8: =SUM(F8:AE8) -> 0
A9: 3 | D9: ו | E9: 1 | AF9: =SUM(F9:AE9) -> 0
A10: 4 | D10: ו | E10: 1 | AF10: =SUM(F10:AE10) -> 0
A11: 5 | D11: ו | E11: 1 | AF11: =SUM(F11:AE11) -> 0
A12: 6 | D12: ו | E12: 1 | AF12: =SUM(F12:AE12) -> 0
A13: 7 | D13: ו | E13: 1 | AF13: =SUM(F13:AE13) -> 0
A14: 8 | D14: ו | E14: 1 | AF14: =SUM(F14:AE14) -> 0
A15: 9 | D15: ו | E15: 1 | AF15: =SUM(F15:AE15) -> 0
A16: 10 | D16: ו | E16: 1 | AF16: =SUM(F16:AE16) -> 0
A17: 11 | D17: ו | E17: 1 | AF17: =SUM(F17:AE17) -> 0
A18: 12 | D18: ו | E18: 1 | AF18: =SUM(F18:AE18) -> 0
... A43: 37 | D43: ו | E43: 1 | AF43: =SUM(F43:AE43) -> 0
C44: אחוזי הצלחה | F44: =IFERROR(AVERAGE(F$7:F$43),0) -> 0 | G44: =IFERROR(AVERAGE(G$7:G$43),0) -> 0 | H44: =IFERROR(AVERAGE(H$7:H$43),0) -> 0 | I44: =IFERROR(AVERAGE(I$7:I$43),0) -> 0 | J44: =IFERROR(AVERAGE(J$7:J$43),0) -> 0 | K44: =IFERROR(AVERAGE(K$7:K$43),0) -> 0 | L44: =IFERROR(AVERAGE(L$7:L$43),0) -> 0 | M44: =IFERROR(AVERAGE(M$7:M$43),0) -> 0 | ... AE44: =IFERROR(AVERAGE(AE$7:AE$43),0) -> 0

Sheet כיתה ו2
D1: נושא | F1: מבנה עשרוני | G1: פעולות בשלמים | K1: פעולות בשלמים | L1: פעולות בשלמים | M1: פעולות בשלמים | N1: פעולות בשברים | R1: משמעות השבר | S1: חקר נתונים | W1: משמעות השבר | X1: מספרים עשרוניים | Y1: משמעות השבר | Z1: מספרים עשרוניים | AA1: פעולות בשברים | AB1: מצולעים | AC1: מצולעים | AD1: מדידות | AE1: מדידות
D2: שאלה | F2: 1 | G2: 2 | K2: 3 | L2: 4 | M2: 5 | N2: 6 | R2: 7 | S2: 8 | W2: 9 | X2: 10 | Y2: 11 | Z2: 12 | AA2: 13 | AB2: 14 | AC2: 15 | AD2: 16 | AE2: 17
D3: תת שאלה | F3: 1 | G3: 2א | H3: 2ב | I3: 2ג | J3: 2ד | K3: 3 | L3: 4 | M3: 5 | N3: 6א | O3: 6ב | P3: 6ג | Q3: 6ד | R3: 7 | S3: 8א | T3: 8ב | U3: 8ג | V3: 8ד | W3: 9 | X3: 10 | Y3: 11 | Z3: 12 | AA3: 13 | AB3: 14 | AC3: 15 | AD3: 16 | AE3: 17
D4: תת נושא | F4: כתיבת מספר | G4: סדר פעולות | H4: חיסור | I4: כפל דו בדו | J4: חילוק | K4: משוואה בחיבור ואי שיוויון | L4: אומדן בכפל | M4: התאמת תרגיל לשאלה מילולית | N4: חיבור | O4: חיבור | P4: חיסור | Q4: כפל כחיבור חוזר | R4: השוואת שברים | S4: קריאת דיאגרמה | T4: קריאת דיאגרמה | U4: קריאת דיאגרמה | V4: איזה חלק | W4: השבר כחלק מכמות | X4: מהות העשרוני | Y4: השבר על ישר מספרים | Z4: סדרות | AA4: שאלה מילולית | AB4: משפחת המרובעים | AC4: גובה במשולש | AD4: שטח משולש | AE4: שטחים מורכבים
D5: רמת חשיבה | F5: חשיבה אלגוריתמית | G5: חשיבה אלגוריתמית | H5: חשיבה אלגוריתמית | I5: חשיבה אלגוריתמית | J5: חשיבה אלגוריתמית | K5: חשיבה תהליכית | L5: חשיבה תהליכית | M5: חשיבה תהליכית | N5: חשיבה אלגוריתמית | O5: חשיבה אלגוריתמית | P5: חשיבה אלגוריתמית | Q5: חשיבה אלגוריתמית | R5: חשיבה תהליכית | S5: ידע וזיהוי | T5: ידע וזיהוי | U5: ידע וזיהוי | V5: חשיבה תהליכית | W5: ידע וזיהוי | X5: ידע וזיהוי | Y5: ידע וזיהוי | Z5: חשיבה אלגוריתמית | AA5: חשיבה תהליכית | AB5: ידע וזיהוי | AC5: ידע וזיהוי | AD5: חשיבה אלגוריתמית | AE5: חשיבה תהליכית
A6: מס' | B6: ת.ז התלמיד | C6: שם התלמיד | D6: שכבה | E6: כיתה | F6: ניקוד | G6: ניקוד | H6: ניקוד | I6: ניקוד | J6: ניקוד | K6: ניקוד | L6: ניקוד | M6: ניקוד | N6: ניקוד | O6: ניקוד | P6: ניקוד | Q6: ניקוד | R6: ניקוד | S6: ניקוד | T6: ניקוד | U6: ניקוד | V6: ניקוד | W6: ניקוד | X6: ניקוד | Y6: ניקוד | Z6: ניקוד | AA6: ניקוד | AB6: ניקוד | AC6: ניקוד | AD6: ניקוד | AE6: ניקוד | AF6: ציון מבחן
A7: 1 | D7: ו | E7: 2 | AF7: =SUM(F7:AE7) -> 0
A8: 2 | D8: ו | E8: 2 | AF8: =SUM(F8:AE8) -> 0
A9: 3 | D9: ו | E9: 2 | AF9: =SUM(F9:AE9) -> 0
A10: 4 | D10: ו | E10: 2 | AF10: =SUM(F10:AE10) -> 0
A11: 5 | D11: ו | E11: 2 | AF11: =SUM(F11:AE11) -> 0
A12: 6 | D12: ו | E12: 2 | AF12: =SUM(F12:AE12) -> 0
A13: 7 | D13: ו | E13: 2 | AF13: =SUM(F13:AE13) -> 0
A14: 8 | D14: ו | E14: 2 | AF14: =SUM(F14:AE14) -> 0
A15: 9 | D15: ו | E15: 2 | AF15: =SUM(F15:AE15) -> 0
A16: 10 | D16: ו | E16: 2 | AF16: =SUM(F16:AE16) -> 0
A17: 11 | D17: ו | E17: 2 | AF17: =SUM(F17:AE17) -> 0
A18: 12 | D18: ו | E18: 2 | AF18: =SUM(F18:AE18) -> 0
... A43: 37 | D43: ו | E43: 2 | AF43: =SUM(F43:AE43) -> 0
C44: אחוזי הצלחה | F44: =IFERROR(AVERAGE(F$7:F$43),0) -> 0 | G44: =IFERROR(AVERAGE(G$7:G$43),0) -> 0 | H44: =IFERROR(AVERAGE(H$7:H$43),0) -> 0 | I44: =IFERROR(AVERAGE(I$7:I$43),0) -> 0 | J44: =IFERROR(AVERAGE(J$7:J$43),0) -> 0 | K44: =IFERROR(AVERAGE(K$7:K$43),0) -> 0 | L44: =IFERROR(AVERAGE(L$7:L$43),0) -> 0 | M44: =IFERROR(AVERAGE(M$7:M$43),0) -> 0 | ... AE44: =IFERROR(AVERAGE(AE$7:AE$43),0) -> 0

Sheet כיתה ו3
D1: נושא | F1: מבנה עשרוני | G1: פעולות בשלמים | K1: פעולות בשלמים | L1: פעולות בשלמים | M1: פעולות בשלמים | N1: פעולות בשברים | R1: משמעות השבר | S1: חקר נתונים | W1: משמעות השבר | X1: מספרים עשרוניים | Y1: משמעות השבר | Z1: מספרים עשרוניים | AA1: פעולות בשברים | AB1: מצולעים | AC1: מצולעים | AD1: מדידות | AE1: מדידות
D2: שאלה | F2: 1 | G2: 2 | K2: 3 | L2: 4 | M2: 5 | N2: 6 | R2: 7 | S2: 8 | W2: 9 | X2: 10 | Y2: 11 | Z2: 12 | AA2: 13 | AB2: 14 | AC2: 15 | AD2: 16 | AE2: 17
D3: תת שאלה | F3: 1 | G3: 2א | H3: 2ב | I3: 2ג | J3: 2ד | K3: 3 | L3: 4 | M3: 5 | N3: 6א | O3: 6ב | P3: 6ג | Q3: 6ד | R3: 7 | S3: 8א | T3: 8ב | U3: 8ג | V3: 8ד | W3: 9 | X3: 10 | Y3: 11 | Z3: 12 | AA3: 13 | AB3: 14 | AC3: 15 | AD3: 16 | AE3: 17
D4: תת נושא | F4: כתיבת מספר | G4: סדר פעולות | H4: חיסור | I4: כפל דו בדו | J4: חילוק | K4: משוואה בחיבור ואי שיוויון | L4: אומדן בכפל | M4: התאמת תרגיל לשאלה מילולית | N4: חיבור | O4: חיבור | P4: חיסור | Q4: כפל כחיבור חוזר | R4: השוואת שברים | S4: קריאת דיאגרמה | T4: קריאת דיאגרמה | U4: קריאת דיאגרמה | V4: איזה חלק | W4: השבר כחלק מכמות | X4: מהות העשרוני | Y4: השבר על ישר מספרים | Z4: סדרות | AA4: שאלה מילולית | AB4: משפחת המרובעים | AC4: גובה במשולש | AD4: שטח משולש | AE4: שטחים מורכבים
D5: רמת חשיבה | F5: חשיבה אלגוריתמית | G5: חשיבה אלגוריתמית | H5: חשיבה אלגוריתמית | I5: חשיבה אלגוריתמית | J5: חשיבה אלגוריתמית | K5: חשיבה תהליכית | L5: חשיבה תהליכית | M5: חשיבה תהליכית | N5: חשיבה אלגוריתמית | O5: חשיבה אלגוריתמית | P5: חשיבה אלגוריתמית | Q5: חשיבה אלגוריתמית | R5: חשיבה תהליכית | S5: ידע וזיהוי | T5: ידע וזיהוי | U5: ידע וזיהוי | V5: חשיבה תהליכית | W5: ידע וזיהוי | X5: ידע וזיהוי | Y5: ידע וזיהוי | Z5: חשיבה אלגוריתמית | AA5: חשיבה תהליכית | AB5: ידע וזיהוי | AC5: ידע וזיהוי | AD5: חשיבה אלגוריתמית | AE5: חשיבה תהליכית
A6: מס' | B6: ת.ז התלמיד | C6: שם התלמיד | D6: שכבה | E6: כיתה | F6: ניקוד | G6: ניקוד | H6: ניקוד | I6: ניקוד | J6: ניקוד | K6: ניקוד | L6: ניקוד | M6: ניקוד | N6: ניקוד | O6: ניקוד | P6: ניקוד | Q6: ניקוד | R6: ניקוד | S6: ניקוד | T6: ניקוד | U6: ניקוד | V6: ניקוד | W6: ניקוד | X6: ניקוד | Y6: ניקוד | Z6: ניקוד | AA6: ניקוד | AB6: ניקוד | AC6: ניקוד | AD6: ניקוד | AE6: ניקוד | AF6: ציון מבחן
A7: 1 | D7: ו | E7: 3 | AF7: =SUM(F7:AE7) -> 0
A8: 2 | D8: ו | E8: 3 | AF8: =SUM(F8:AE8) -> 0
A9: 3 | D9: ו | E9: 3 | AF9: =SUM(F9:AE9) -> 0
A10: 4 | D10: ו | E10: 3 | AF10: =SUM(F10:AE10) -> 0
A11: 5 | D11: ו | E11: 3 | AF11: =SUM(F11:AE11) -> 0
A12: 6 | D12: ו | E12: 3 | AF12: =SUM(F12:AE12) -> 0
A13: 7 | D13: ו | E13: 3 | AF13: =SUM(F13:AE13) -> 0
A14: 8 | D14: ו | E14: 3 | AF14: =SUM(F14:AE14) -> 0
A15: 9 | D15: ו | E15: 3 | AF15: =SUM(F15:AE15) -> 0
A16: 10 | D16: ו | E16: 3 | AF16: =SUM(F16:AE16) -> 0
A17: 11 | D17: ו | E17: 3 | AF17: =SUM(F17:AE17) -> 0
A18: 12 | D18: ו | E18: 3 | AF18: =SUM(F18:AE18) -> 0
... A43: 37 | D43: ו | E43: 3 | AF43: =SUM(F43:AE43) -> 0
C44: אחוזי הצלחה | F44: =IFERROR(AVERAGE(F$7:F$43),0) -> 0 | G44: =IFERROR(AVERAGE(G$7:G$43),0) -> 0 | H44: =IFERROR(AVERAGE(H$7:H$43),0) -> 0 | I44: =IFERROR(AVERAGE(I$7:I$43),0) -> 0 | J44: =IFERROR(AVERAGE(J$7:J$43),0) -> 0 | K44: =IFERROR(AVERAGE(K$7:K$43),0) -> 0 | L44: =IFERROR(AVERAGE(L$7:L$43),0) -> 0 | M44: =IFERROR(AVERAGE(M$7:M$43),0) -> 0 | ... AE44: =IFERROR(AVERAGE(AE$7:AE$43),0) -> 0

Sheet כיתה ו4
D1: נושא | F1: מבנה עשרוני | G1: פעולות בשלמים | K1: פעולות בשלמים | L1: פעולות בשלמים | M1: פעולות בשלמים | N1: פעולות בשברים | R1: משמעות השבר | S1: חקר נתונים | W1: משמעות השבר | X1: מספרים עשרוניים | Y1: משמעות השבר | Z1: מספרים עשרוניים | AA1: פעולות בשברים | AB1: מצולעים | AC1: מצולעים | AD1: מדידות | AE1: מדידות
D2: שאלה | F2: 1 | G2: 2 | K2: 3 | L2: 4 | M2: 5 | N2: 6 | R2: 7 | S2: 8 | W2: 9 | X2: 10 | Y2: 11 | Z2: 12 | AA2: 13 | AB2: 14 | AC2: 15 | AD2: 16 | AE2: 17
D3: תת שאלה | F3: 1 | G3: 2א | H3: 2ב | I3: 2ג | J3: 2ד | K3: 3 | L3: 4 | M3: 5 | N3: 6א | O3: 6ב | P3: 6ג | Q3: 6ד | R3: 7 | S3: 8א | T3: 8ב | U3: 8ג | V3: 8ד | W3: 9 | X3: 10 | Y3: 11 | Z3: 12 | AA3: 13 | AB3: 14 | AC3: 15 | AD3: 16 | AE3: 17
D4: תת נושא | F4: כתיבת מספר | G4: סדר פעולות | H4: חיסור | I4: כפל דו בדו | J4: חילוק | K4: משוואה בחיבור ואי שיוויון | L4: אומדן בכפל | M4: התאמת תרגיל לשאלה מילולית | N4: חיבור | O4: חיבור | P4: חיסור | Q4: כפל כחיבור חוזר | R4: השוואת שברים | S4: קריאת דיאגרמה | T4: קריאת דיאגרמה | U4: קריאת דיאגרמה | V4: איזה חלק | W4: השבר כחלק מכמות | X4: מהות העשרוני | Y4: השבר על ישר מספרים | Z4: סדרות | AA4: שאלה מילולית | AB4: משפחת המרובעים | AC4: גובה במשולש | AD4: שטח משולש | AE4: שטחים מורכבים
D5: רמת חשיבה | F5: חשיבה אלגוריתמית | G5: חשיבה אלגוריתמית | H5: חשיבה אלגוריתמית | I5: חשיבה אלגוריתמית | J5: חשיבה אלגוריתמית | K5: חשיבה תהליכית | L5: חשיבה תהליכית | M5: חשיבה תהליכית | N5: חשיבה אלגוריתמית | O5: חשיבה אלגוריתמית | P5: חשיבה אלגוריתמית | Q5: חשיבה אלגוריתמית | R5: חשיבה תהליכית | S5: ידע וזיהוי | T5: ידע וזיהוי | U5: ידע וזיהוי | V5: חשיבה תהליכית | W5: ידע וזיהוי | X5: ידע וזיהוי | Y5: ידע וזיהוי | Z5: חשיבה אלגוריתמית | AA5: חשיבה תהליכית | AB5: ידע וזיהוי | AC5: ידע וזיהוי | AD5: חשיבה אלגוריתמית | AE5: חשיבה תהליכית
A6: מס' | B6: ת.ז התלמיד | C6: שם התלמיד | D6: שכבה | E6: כיתה | F6: ניקוד | G6: ניקוד | H6: ניקוד | I6: ניקוד | J6: ניקוד | K6: ניקוד | L6: ניקוד | M6: ניקוד | N6: ניקוד | O6: ניקוד | P6: ניקוד | Q6: ניקוד | R6: ניקוד | S6: ניקוד | T6: ניקוד | U6: ניקוד | V6: ניקוד | W6: ניקוד | X6: ניקוד | Y6: ניקוד | Z6: ניקוד | AA6: ניקוד | AB6: ניקוד | AC6: ניקוד | AD6: ניקוד | AE6: ניקוד | AF6: ציון מבחן
A7: 1 | D7: ו | E7: 4 | AF7: =SUM(F7:AE7) -> 0
A8: 2 | D8: ו | E8: 4 | AF8: =SUM(F8:AE8) -> 0
A9: 3 | D9: ו | E9: 4 | AF9: =SUM(F9:AE9) -> 0
A10: 4 | D10: ו | E10: 4 | AF10: =SUM(F10:AE10) -> 0
A11: 5 | D11: ו | E11: 4 | AF11: =SUM(F11:AE11) -> 0
A12: 6 | D12: ו | E12: 4 | AF12: =SUM(F12:AE12) -> 0
A13: 7 | D13: ו | E13: 4 | AF13: =SUM(F13:AE13) -> 0
A14: 8 | D14: ו | E14: 4 | AF14: =SUM(F14:AE14) -> 0
A15: 9 | D15: ו | E15: 4 | AF15: =SUM(F15:AE15) -> 0
A16: 10 | D16: ו | E16: 4 | AF16: =SUM(F16:AE16) -> 0
A17: 11 | D17: ו | E17: 4 | AF17: =SUM(F17:AE17) -> 0
A18: 12 | D18: ו | E18: 4 | AF18: =SUM(F18:AE18) -> 0
... A43: 37 | D43: ו | E43: 4 | AF43: =SUM(F43:AE43) -> 0
C44: אחוזי הצלחה | F44: =IFERROR(AVERAGE(F$7:F$43),0) -> 0 | G44: =IFERROR(AVERAGE(G$7:G$43),0) -> 0 | H44: =IFERROR(AVERAGE(H$7:H$43),0) -> 0 | I44: =IFERROR(AVERAGE(I$7:I$43),0) -> 0 | J44: =IFERROR(AVERAGE(J$7:J$43),0) -> 0 | K44: =IFERROR(AVERAGE(K$7:K$43),0) -> 0 | L44: =IFERROR(AVERAGE(L$7:L$43),0) -> 0 | M44: =IFERROR(AVERAGE(M$7:M$43),0) -> 0 | ... AE44: =IFERROR(AVERAGE(AE$7:AE$43),0) -> 0

Sheet כיתה ו5
D1: נושא | F1: מבנה עשרוני | G1: פעולות בשלמים | K1: פעולות בשלמים | L1: פעולות בשלמים | M1: פעולות בשלמים | N1: פעולות בשברים | R1: משמעות השבר | S1: חקר נתונים | W1: משמעות השבר | X1: מספרים עשרוניים | Y1: משמעות השבר | Z1: מספרים עשרוניים | AA1: פעולות בשברים | AB1: מצולעים | AC1: מצולעים | AD1: מדידות | AE1: מדידות
D2: שאלה | F2: 1 | G2: 2 | K2: 3 | L2: 4 | M2: 5 | N2: 6 | R2: 7 | S2: 8 | W2: 9 | X2: 10 | Y2: 11 | Z2: 12 | AA2: 13 | AB2: 14 | AC2: 15 | AD2: 16 | AE2: 17
D3: תת שאלה | F3: 1 | G3: 2א | H3: 2ב | I3: 2ג | J3: 2ד | K3: 3 | L3: 4 | M3: 5 | N3: 6א | O3: 6ב | P3: 6ג | Q3: 6ד | R3: 7 | S3: 8א | T3: 8ב | U3: 8ג | V3: 8ד | W3: 9 | X3: 10 | Y3: 11 | Z3: 12 | AA3: 13 | AB3: 14 | AC3: 15 | AD3: 16 | AE3: 17
D4: תת נושא | F4: כתיבת מספר | G4: סדר פעולות | H4: חיסור | I4: כפל דו בדו | J4: חילוק | K4: משוואה בחיבור ואי שיוויון | L4: אומדן בכפל | M4: התאמת תרגיל לשאלה מילולית | N4: חיבור | O4: חיבור | P4: חיסור | Q4: כפל כחיבור חוזר | R4: השוואת שברים | S4: קריאת דיאגרמה | T4: קריאת דיאגרמה | U4: קריאת דיאגרמה | V4: איזה חלק | W4: השבר כחלק מכמות | X4: מהות העשרוני | Y4: השבר על ישר מספרים | Z4: סדרות | AA4: שאלה מילולית | AB4: משפחת המרובעים | AC4: גובה במשולש | AD4: שטח משולש | AE4: שטחים מורכבים
D5: רמת חשיבה | F5: חשיבה אלגוריתמית | G5: חשיבה אלגוריתמית | H5: חשיבה אלגוריתמית | I5: חשיבה אלגוריתמית | J5: חשיבה אלגוריתמית | K5: חשיבה תהליכית | L5: חשיבה תהליכית | M5: חשיבה תהליכית | N5: חשיבה אלגוריתמית | O5: חשיבה אלגוריתמית | P5: חשיבה אלגוריתמית | Q5: חשיבה אלגוריתמית | R5: חשיבה תהליכית | S5: ידע וזיהוי | T5: ידע וזיהוי | U5: ידע וזיהוי | V5: חשיבה תהליכית | W5: ידע וזיהוי | X5: ידע וזיהוי | Y5: ידע וזיהוי | Z5: חשיבה אלגוריתמית | AA5: חשיבה תהליכית | AB5: ידע וזיהוי | AC5: ידע וזיהוי | AD5: חשיבה אלגוריתמית | AE5: חשיבה תהליכית
A6: מס' | B6: ת.ז התלמיד | C6: שם התלמיד | D6: שכבה | E6: כיתה | F6: ניקוד | G6: ניקוד | H6: ניקוד | I6: ניקוד | J6: ניקוד | K6: ניקוד | L6: ניקוד | M6: ניקוד | N6: ניקוד | O6: ניקוד | P6: ניקוד | Q6: ניקוד | R6: ניקוד | S6: ניקוד | T6: ניקוד | U6: ניקוד | V6: ניקוד | W6: ניקוד | X6: ניקוד | Y6: ניקוד | Z6: ניקוד | AA6: ניקוד | AB6: ניקוד | AC6: ניקוד | AD6: ניקוד | AE6: ניקוד | AF6: ציון מבחן
A7: 1 | D7: ו | E7: 5 | AF7: =SUM(F7:AE7) -> 0
A8: 2 | D8: ו | E8: 5 | AF8: =SUM(F8:AE8) -> 0
A9: 3 | D9: ו | E9: 5 | AF9: =SUM(F9:AE9) -> 0
A10: 4 | D10: ו | E10: 5 | AF10: =SUM(F10:AE10) -> 0
A11: 5 | D11: ו | E11: 5 | AF11: =SUM(F11:AE11) -> 0
A12: 6 | D12: ו | E12: 5 | AF12: =SUM(F12:AE12) -> 0
A13: 7 | D13: ו | E13: 5 | AF13: =SUM(F13:AE13) -> 0
A14: 8 | D14: ו | E14: 5 | AF14: =SUM(F14:AE14) -> 0
A15: 9 | D15: ו | E15: 5 | AF15: =SUM(F15:AE15) -> 0
A16: 10 | D16: ו | E16: 5 | AF16: =SUM(F16:AE16) -> 0
A17: 11 | D17: ו | E17: 5 | AF17: =SUM(F17:AE17) -> 0
A18: 12 | D18: ו | E18: 5 | AF18: =SUM(F18:AE18) -> 0
... A43: 37 | D43: ו | E43: 5 | AF43: =SUM(F43:AE43) -> 0
C44: אחוזי הצלחה | F44: =IFERROR(AVERAGE(F$7:F$43),0) -> 0 | G44: =IFERROR(AVERAGE(G$7:G$43),0) -> 0 | H44: =IFERROR(AVERAGE(H$7:H$43),0) -> 0 | I44: =IFERROR(AVERAGE(I$7:I$43),0) -> 0 | J44: =IFERROR(AVERAGE(J$7:J$43),0) -> 0 | K44: =IFERROR(AVERAGE(K$7:K$43),0) -> 0 | L44: =IFERROR(AVERAGE(L$7:L$43),0) -> 0 | M44: =IFERROR(AVERAGE(M$7:M$43),0) -> 0 | ... AE44: =IFERROR(AVERAGE(AE$7:AE$43),0) -> 0

Sheet דשבורד שכבה ו
A1: דשבורד הישגים והשוואת כיתות — שכבה ו׳
A2: הנתונים כוללים תלמידים ניגשים בלבד ומתעדכנים אוטומטית
A4: ממוצע שכבה | D4: תלמידים רשומים | G4: תלמידים ניגשים | J4: תלמידים נעדרים | M4: אחוז ביצוע | Q4: מספר כיתות
A5: {=IFERROR((SUMPRODUCT('כיתה ו1'!$AF$7:$AF$43,--('כיתה ו1'!$C$7:$C$43<>""),--(MMULT(--('כיתה ו1'!$F$7:$AE$43<>""),TRANSPOSE(COLUMN('כיתה ו1'!$F$7:$AE$7)^0))>0))+SUMPRODUCT('כיתה ו2'!$AF$7:$AF$43,--('כיתה ו2'!$C$7:$C$43<>""),--(MMULT(--('כיתה ו2'!$F$7:$AE$43<>""),TRANSPOSE(COLUMN('כיתה ו2'!$F$7:$AE$7)^0))>0))+SUMPRODUCT('כיתה ו3'!$AF$7:$AF$43,--('כיתה ו3'!$C$7:$C$43<>""),--(MMULT(--('כיתה ו3'!$F$7:$AE$43<>""),TRANSPOSE(COLUMN('כיתה ו3'!$F$7:$AE$7)^0))>0))+SUMPRODUCT('כיתה ו4'!$AF$7:$AF$43,--('כיתה ו4'!$C$7:$C$43<>""),--(MMULT(--('כיתה ו4'!$F$7:$AE$43<>""),TRANSPOSE(COLUMN('כיתה ו4'!$F$7:$AE$7)^0))>0))+SUMPRODUCT('כיתה ו5'!$AF$7:$AF$43,--('כיתה ו5'!$C$7:$C$43<>""),--(MMULT(--('כיתה ו5'!$F$7:$AE$43<>""),TRANSPOSE(COLUMN('כיתה ו5'!$F$7:$AE$7)^0))>0)))/((COUNTA('כיתה ו1'!$C$7:$C$43)-SUMPRODUCT(--('כיתה ו1'!$C$7:$C$43<>""),--(MMULT(--('כיתה ו1'!$F$7:$AE$43<>""),TRANSPOSE(COLUMN('כיתה ו1'!$F$7:$AE$7)^0))=0)))+(COUNTA('כיתה ו2'!$C$7:$C$43)-SUMPRODUCT(--('כיתה ו2'!$C$7:$C$43<>""),--(MMULT(--('כיתה ו2'!$F$7:$AE$43<>""),TRANSPOSE(COLUMN('כיתה ו2'!$F$7:$AE$7)^0))=0)))+(COUNTA('כיתה ו3'!$C$7:$C$43)-SUMPRODUCT(--('כיתה ו3'!$C$7:$C$43<>""),--(MMULT(--('כיתה ו3'!$F$7:$AE$43<>""),TRANSPOSE(COLUMN('כיתה ו3'!$F$7:$AE$7)^0))=0)))+(COUNTA('כיתה ו4'!$C$7:$C$43)-SUMPRODUCT(--('כיתה ו4'!$C$7:$C$43<>""),--(MMULT(--('כיתה ו4'!$F$7:$AE$43<>""),TRANSPOSE(COLUMN('כיתה ו4'!$F$7:$AE$7)^0))=0)))+(COUNTA('כיתה ו5'!$C$7:$C$43)-SUMPRODUCT(--('כיתה ו5'!$C$7:$C$43<>""),--(MMULT(--('כיתה ו5'!$F$7:$AE$43<>""),TRANSPOSE(COLUMN('כיתה ו5'!$F$7:$AE$7)^0))=0)))),0)} -> 0 | D5: =(COUNTA('כיתה ו1'!$C$7:$C$43)+COUNTA('כיתה ו2'!$C$7:$C$43)+COUNTA('כיתה ו3'!$C$7:$C$43)+COUNTA('כיתה ו4'!$C$7:$C$43)+COUNTA('כיתה ו5'!$C$7:$C$43)) -> 0 | G5: {=((COUNTA('כיתה ו1'!$C$7:$C$43)-SUMPRODUCT(--('כיתה ו1'!$C$7:$C$43<>""),--(MMULT(--('כיתה ו1'!$F$7:$AE$43<>""),TRANSPOSE(COLUMN('כיתה ו1'!$F$7:$AE$7)^0))=0)))+(COUNTA('כיתה ו2'!$C$7:$C$43)-SUMPRODUCT(--('כיתה ו2'!$C$7:$C$43<>""),--(MMULT(--('כיתה ו2'!$F$7:$AE$43<>""),TRANSPOSE(COLUMN('כיתה ו2'!$F$7:$AE$7)^0))=0)))+(COUNTA('כיתה ו3'!$C$7:$C$43)-SUMPRODUCT(--('כיתה ו3'!$C$7:$C$43<>""),--(MMULT(--('כיתה ו3'!$F$7:$AE$43<>""),TRANSPOSE(COLUMN('כיתה ו3'!$F$7:$AE$7)^0))=0)))+(COUNTA('כיתה ו4'!$C$7:$C$43)-SUMPRODUCT(--('כיתה ו4'!$C$7:$C$43<>""),--(MMULT(--('כיתה ו4'!$F$7:$AE$43<>""),TRANSPOSE(COLUMN('כיתה ו4'!$F$7:$AE$7)^0))=0)))+(COUNTA('כיתה ו5'!$C$7:$C$43)-SUMPRODUCT(--('כיתה ו5'!$C$7:$C$43<>""),--(MMULT(--('כיתה ו5'!$F$7:$AE$43<>""),TRANSPOSE(COLUMN('כיתה ו5'!$F$7:$AE$7)^0))=0))))} -> 0 | J5: {=(SUMPRODUCT(--('כיתה ו1'!$C$7:$C$43<>""),--(MMULT(--('כיתה ו1'!$F$7:$AE$43<>""),TRANSPOSE(COLUMN('כיתה ו1'!$F$7:$AE$7)^0))=0))+SUMPRODUCT(--('כיתה ו2'!$C$7:$C$43<>""),--(MMULT(--('כיתה ו2'!$F$7:$AE$43<>""),TRANSPOSE(COLUMN('כיתה ו2'!$F$7:$AE$7)^0))=0))+SUMPRODUCT(--('כיתה ו3'!$C$7:$C$43<>""),--(MMULT(--('כיתה ו3'!$F$7:$AE$43<>""),TRANSPOSE(COLUMN('כיתה ו3'!$F$7:$AE$7)^0))=0))+SUMPRODUCT(--('כיתה ו4'!$C$7:$C$43<>""),--(MMULT(--('כיתה ו4'!$F$7:$AE$43<>""),TRANSPOSE(COLUMN('כיתה ו4'!$F$7:$AE$7)^0))=0))+SUMPRODUCT(--('כיתה ו5'!$C$7:$C$43<>""),--(MMULT(--('כיתה ו5'!$F$7:$AE$43<>""),TRANSPOSE(COLUMN('כיתה ו5'!$F$7:$AE$7)^0))=0)))} -> 0 | M5: {=IFERROR(((COUNTA('כיתה ו1'!$C$7:$C$43)-SUMPRODUCT(--('כיתה ו1'!$C$7:$C$43<>""),--(MMULT(--('כיתה ו1'!$F$7:$AE$43<>""),TRANSPOSE(COLUMN('כיתה ו1'!$F$7:$AE$7)^0))=0)))+(COUNTA('כיתה ו2'!$C$7:$C$43)-SUMPRODUCT(--('כיתה ו2'!$C$7:$C$43<>""),--(MMULT(--('כיתה ו2'!$F$7:$AE$43<>""),TRANSPOSE(COLUMN('כיתה ו2'!$F$7:$AE$7)^0))=0)))+(COUNTA('כיתה ו3'!$C$7:$C$43)-SUMPRODUCT(--('כיתה ו3'!$C$7:$C$43<>""),--(MMULT(--('כיתה ו3'!$F$7:$AE$43<>""),TRANSPOSE(COLUMN('כיתה ו3'!$F$7:$AE$7)^0))=0)))+(COUNTA('כיתה ו4'!$C$7:$C$43)-SUMPRODUCT(--('כיתה ו4'!$C$7:$C$43<>""),--(MMULT(--('כיתה ו4'!$F$7:$AE$43<>""),TRANSPOSE(COLUMN('כיתה ו4'!$F$7:$AE$7)^0))=0)))+(COUNTA('כיתה ו5'!$C$7:$C$43)-SUMPRODUCT(--('כיתה ו5'!$C$7:$C$43<>""),--(MMULT(--('כיתה ו5'!$F$7:$AE$43<>""),TRANSPOSE(COLUMN('כיתה ו5'!$F$7:$AE$7)^0))=0))))/(COUNTA('כיתה ו1'!$C$7:$C$43)+COUNTA('כיתה ו2'!$C$7:$C$43)+COUNTA('כיתה ו3'!$C$7:$C$43)+COUNTA('כיתה ו4'!$C$7:$C$43)+COUNTA('כיתה ו5'!$C$7:$C$43)),0)} -> 0 | Q5: =5 -> 5
A8: כיתה | B8: ממוצע | C8: 86–100 | D8: 70–85 | E8: 55–69 | F8: 0–54 | G8: ניגשים
A9: ו1 | B9: {=IFERROR(SUMPRODUCT('כיתה ו1'!$AF$7:$AF$43,--('כיתה ו1'!$C$7:$C$43<>""),--(MMULT(--('כיתה ו1'!$F$7:$AE$43<>""),TRANSPOSE(COLUMN('כיתה ו1'!$F$7:$AE$7)^0))>0))/(COUNTA('כיתה ו1'!$C$7:$C$43)-SUMPRODUCT(--('כיתה ו1'!$C$7:$C$43<>""),--(MMULT(--('כיתה ו1'!$F$7:$AE$43<>""),TRANSPOSE(COLUMN('כיתה ו1'!$F$7:$AE$7)^0))=0))),0)} -> 0 | C9: {=SUMPRODUCT(--('כיתה ו1'!$C$7:$C$43<>""),--('כיתה ו1'!$AF$7:$AF$43>=86),--('כיתה ו1'!$AF$7:$AF$43<=100),--(MMULT(--('כיתה ו1'!$F$7:$AE$43<>""),TRANSPOSE(COLUMN('כיתה ו1'!$F$7:$AE$7)^0))>0))} -> 0 | D9: {=SUMPRODUCT(--('כיתה ו1'!$C$7:$C$43<>""),--('כיתה ו1'!$AF$7:$AF$43>=70),--('כיתה ו1'!$AF$7:$AF$43<=85),--(MMULT(--('כיתה ו1'!$F$7:$AE$43<>""),TRANSPOSE(COLUMN('כיתה ו1'!$F$7:$AE$7)^0))>0))} -> 0 | E9: {=SUMPRODUCT(--('כיתה ו1'!$C$7:$C$43<>""),--('כיתה ו1'!$AF$7:$AF$43>=55),--('כיתה ו1'!$AF$7:$AF$43<=69),--(MMULT(--('כיתה ו1'!$F$7:$AE$43<>""),TRANSPOSE(COLUMN('כיתה ו1'!$F$7:$AE$7)^0))>0))} -> 0 | F9: {=SUMPRODUCT(--('כיתה ו1'!$C$7:$C$43<>""),--('כיתה ו1'!$AF$7:$AF$43>=0),--('כיתה ו1'!$AF$7:$AF$43<=54),--(MMULT(--('כיתה ו1'!$F$7:$AE$43<>""),TRANSPOSE(COLUMN('כיתה ו1'!$F$7:$AE$7)^0))>0))} -> 0 | G9: {=(COUNTA('כיתה ו1'!$C$7:$C$43)-SUMPRODUCT(--('כיתה ו1'!$C$7:$C$43<>""),--(MMULT(--('כיתה ו1'!$F$7:$AE$43<>""),TRANSPOSE(COLUMN('כיתה ו1'!$F$7:$AE$7)^0))=0)))} -> 0
A10: ו2 | B10: {=IFERROR(SUMPRODUCT('כיתה ו2'!$AF$7:$AF$43,--('כיתה ו2'!$C$7:$C$43<>""),--(MMULT(--('כיתה ו2'!$F$7:$AE$43<>""),TRANSPOSE(COLUMN('כיתה ו2'!$F$7:$AE$7)^0))>0))/(COUNTA('כיתה ו2'!$C$7:$C$43)-SUMPRODUCT(--('כיתה ו2'!$C$7:$C$43<>""),--(MMULT(--('כיתה ו2'!$F$7:$AE$43<>""),TRANSPOSE(COLUMN('כיתה ו2'!$F$7:$AE$7)^0))=0))),0)} -> 0 | C10: {=SUMPRODUCT(--('כיתה ו2'!$C$7:$C$43<>""),--('כיתה ו2'!$AF$7:$AF$43>=86),--('כיתה ו2'!$AF$7:$AF$43<=100),--(MMULT(--('כיתה ו2'!$F$7:$AE$43<>""),TRANSPOSE(COLUMN('כיתה ו2'!$F$7:$AE$7)^0))>0))} -> 0 | D10: {=SUMPRODUCT(--('כיתה ו2'!$C$7:$C$43<>""),--('כיתה ו2'!$AF$7:$AF$43>=70),--('כיתה ו2'!$AF$7:$AF$43<=85),--(MMULT(--('כיתה ו2'!$F$7:$AE$43<>""),TRANSPOSE(COLUMN('כיתה ו2'!$F$7:$AE$7)^0))>0))} -> 0 | E10: {=SUMPRODUCT(--('כיתה ו2'!$C$7:$C$43<>""),--('כיתה ו2'!$AF$7:$AF$43>=55),--('כיתה ו2'!$AF$7:$AF$43<=69),--(MMULT(--('כיתה ו2'!$F$7:$AE$43<>""),TRANSPOSE(COLUMN('כיתה ו2'!$F$7:$AE$7)^0))>0))} -> 0 | F10: {=SUMPRODUCT(--('כיתה ו2'!$C$7:$C$43<>""),--('כיתה ו2'!$AF$7:$AF$43>=0),--('כיתה ו2'!$AF$7:$AF$43<=54),--(MMULT(--('כיתה ו2'!$F$7:$AE$43<>""),TRANSPOSE(COLUMN('כיתה ו2'!$F$7:$AE$7)^0))>0))} -> 0 | G10: {=(COUNTA('כיתה ו2'!$C$7:$C$43)-SUMPRODUCT(--('כיתה ו2'!$C$7:$C$43<>""),--(MMULT(--('כיתה ו2'!$F$7:$AE$43<>""),TRANSPOSE(COLUMN('כיתה ו2'!$F$7:$AE$7)^0))=0)))} -> 0
A11: ו3 | B11: {=IFERROR(SUMPRODUCT('כיתה ו3'!$AF$7:$AF$43,--('כיתה ו3'!$C$7:$C$43<>""),--(MMULT(--('כיתה ו3'!$F$7:$AE$43<>""),TRANSPOSE(COLUMN('כיתה ו3'!$F$7:$AE$7)^0))>0))/(COUNTA('כיתה ו3'!$C$7:$C$43)-SUMPRODUCT(--('כיתה ו3'!$C$7:$C$43<>""),--(MMULT(--('כיתה ו3'!$F$7:$AE$43<>""),TRANSPOSE(COLUMN('כיתה ו3'!$F$7:$AE$7)^0))=0))),0)} -> 0 | C11: {=SUMPRODUCT(--('כיתה ו3'!$C$7:$C$43<>""),--('כיתה ו3'!$AF$7:$AF$43>=86),--('כיתה ו3'!$AF$7:$AF$43<=100),--(MMULT(--('כיתה ו3'!$F$7:$AE$43<>""),TRANSPOSE(COLUMN('כיתה ו3'!$F$7:$AE$7)^0))>0))} -> 0 | D11: {=SUMPRODUCT(--('כיתה ו3'!$C$7:$C$43<>""),--('כיתה ו3'!$AF$7:$AF$43>=70),--('כיתה ו3'!$AF$7:$AF$43<=85),--(MMULT(--('כיתה ו3'!$F$7:$AE$43<>""),TRANSPOSE(COLUMN('כיתה ו3'!$F$7:$AE$7)^0))>0))} -> 0 | E11: {=SUMPRODUCT(--('כיתה ו3'!$C$7:$C$43<>""),--('כיתה ו3'!$AF$7:$AF$43>=55),--('כיתה ו3'!$AF$7:$AF$43<=69),--(MMULT(--('כיתה ו3'!$F$7:$AE$43<>""),TRANSPOSE(COLUMN('כיתה ו3'!$F$7:$AE$7)^0))>0))} -> 0 | F11: {=SUMPRODUCT(--('כיתה ו3'!$C$7:$C$43<>""),--('כיתה ו3'!$AF$7:$AF$43>=0),--('כיתה ו3'!$AF$7:$AF$43<=54),--(MMULT(--('כיתה ו3'!$F$7:$AE$43<>""),TRANSPOSE(COLUMN('כיתה ו3'!$F$7:$AE$7)^0))>0))} -> 0 | G11: {=(COUNTA('כיתה ו3'!$C$7:$C$43)-SUMPRODUCT(--('כיתה ו3'!$C$7:$C$43<>""),--(MMULT(--('כיתה ו3'!$F$7:$AE$43<>""),TRANSPOSE(COLUMN('כיתה ו3'!$F$7:$AE$7)^0))=0)))} -> 0
A12: ו4 | B12: {=IFERROR(SUMPRODUCT('כיתה ו4'!$AF$7:$AF$43,--('כיתה ו4'!$C$7:$C$43<>""),--(MMULT(--('כיתה ו4'!$F$7:$AE$43<>""),TRANSPOSE(COLUMN('כיתה ו4'!$F$7:$AE$7)^0))>0))/(COUNTA('כיתה ו4'!$C$7:$C$43)-SUMPRODUCT(--('כיתה ו4'!$C$7:$C$43<>""),--(MMULT(--('כיתה ו4'!$F$7:$AE$43<>""),TRANSPOSE(COLUMN('כיתה ו4'!$F$7:$AE$7)^0))=0))),0)} -> 0 | C12: {=SUMPRODUCT(--('כיתה ו4'!$C$7:$C$43<>""),--('כיתה ו4'!$AF$7:$AF$43>=86),--('כיתה ו4'!$AF$7:$AF$43<=100),--(MMULT(--('כיתה ו4'!$F$7:$AE$43<>""),TRANSPOSE(COLUMN('כיתה ו4'!$F$7:$AE$7)^0))>0))} -> 0 | D12: {=SUMPRODUCT(--('כיתה ו4'!$C$7:$C$43<>""),--('כיתה ו4'!$AF$7:$AF$43>=70),--('כיתה ו4'!$AF$7:$AF$43<=85),--(MMULT(--('כיתה ו4'!$F$7:$AE$43<>""),TRANSPOSE(COLUMN('כיתה ו4'!$F$7:$AE$7)^0))>0))} -> 0 | E12: {=SUMPRODUCT(--('כיתה ו4'!$C$7:$C$43<>""),--('כיתה ו4'!$AF$7:$AF$43>=55),--('כיתה ו4'!$AF$7:$AF$43<=69),--(MMULT(--('כיתה ו4'!$F$7:$AE$43<>""),TRANSPOSE(COLUMN('כיתה ו4'!$F$7:$AE$7)^0))>0))} -> 0 | F12: {=SUMPRODUCT(--('כיתה ו4'!$C$7:$C$43<>""),--('כיתה ו4'!$AF$7:$AF$43>=0),--('כיתה ו4'!$AF$7:$AF$43<=54),--(MMULT(--('כיתה ו4'!$F$7:$AE$43<>""),TRANSPOSE(COLUMN('כיתה ו4'!$F$7:$AE$7)^0))>0))} -> 0 | G12: {=(COUNTA('כיתה ו4'!$C$7:$C$43)-SUMPRODUCT(--('כיתה ו4'!$C$7:$C$43<>""),--(MMULT(--('כיתה ו4'!$F$7:$AE$43<>""),TRANSPOSE(COLUMN('כיתה ו4'!$F$7:$AE$7)^0))=0)))} -> 0
A13: ו5 | B13: {=IFERROR(SUMPRODUCT('כיתה ו5'!$AF$7:$AF$43,--('כיתה ו5'!$C$7:$C$43<>""),--(MMULT(--('כיתה ו5'!$F$7:$AE$43<>""),TRANSPOSE(COLUMN('כיתה ו5'!$F$7:$AE$7)^0))>0))/(COUNTA('כיתה ו5'!$C$7:$C$43)-SUMPRODUCT(--('כיתה ו5'!$C$7:$C$43<>""),--(MMULT(--('כיתה ו5'!$F$7:$AE$43<>""),TRANSPOSE(COLUMN('כיתה ו5'!$F$7:$AE$7)^0))=0))),0)} -> 0 | C13: {=SUMPRODUCT(--('כיתה ו5'!$C$7:$C$43<>""),--('כיתה ו5'!$AF$7:$AF$43>=86),--('כיתה ו5'!$AF$7:$AF$43<=100),--(MMULT(--('כיתה ו5'!$F$7:$AE$43<>""),TRANSPOSE(COLUMN('כיתה ו5'!$F$7:$AE$7)^0))>0))} -> 0 | D13: {=SUMPRODUCT(--('כיתה ו5'!$C$7:$C$43<>""),--('כיתה ו5'!$AF$7:$AF$43>=70),--('כיתה ו5'!$AF$7:$AF$43<=85),--(MMULT(--('כיתה ו5'!$F$7:$AE$43<>""),TRANSPOSE(COLUMN('כיתה ו5'!$F$7:$AE$7)^0))>0))} -> 0 | E13: {=SUMPRODUCT(--('כיתה ו5'!$C$7:$C$43<>""),--('כיתה ו5'!$AF$7:$AF$43>=55),--('כיתה ו5'!$AF$7:$AF$43<=69),--(MMULT(--('כיתה ו5'!$F$7:$AE$43<>""),TRANSPOSE(COLUMN('כיתה ו5'!$F$7:$AE$7)^0))>0))} -> 0 | F13: {=SUMPRODUCT(--('כיתה ו5'!$C$7:$C$43<>""),--('כיתה ו5'!$AF$7:$AF$43>=0),--('כיתה ו5'!$AF$7:$AF$43<=54),--(MMULT(--('כיתה ו5'!$F$7:$AE$43<>""),TRANSPOSE(COLUMN('כיתה ו5'!$F$7:$AE$7)^0))>0))} -> 0 | G13: {=(COUNTA('כיתה ו5'!$C$7:$C$43)-SUMPRODUCT(--('כיתה ו5'!$C$7:$C$43<>""),--(MMULT(--('כיתה ו5'!$F$7:$AE$43<>""),TRANSPOSE(COLUMN('כיתה ו5'!$F$7:$AE$7)^0))=0)))} -> 0
A14: שכבה | B14: {=IFERROR((SUMPRODUCT('כיתה ו1'!$AF$7:$AF$43,--('כיתה ו1'!$C$7:$C$43<>""),--(MMULT(--('כיתה ו1'!$F$7:$AE$43<>""),TRANSPOSE(COLUMN('כיתה ו1'!$F$7:$AE$7)^0))>0))+SUMPRODUCT('כיתה ו2'!$AF$7:$AF$43,--('כיתה ו2'!$C$7:$C$43<>""),--(MMULT(--('כיתה ו2'!$F$7:$AE$43<>""),TRANSPOSE(COLUMN('כיתה ו2'!$F$7:$AE$7)^0))>0))+SUMPRODUCT('כיתה ו3'!$AF$7:$AF$43,--('כיתה ו3'!$C$7:$C$43<>""),--(MMULT(--('כיתה ו3'!$F$7:$AE$43<>""),TRANSPOSE(COLUMN('כיתה ו3'!$F$7:$AE$7)^0))>0))+SUMPRODUCT('כיתה ו4'!$AF$7:$AF$43,--('כיתה ו4'!$C$7:$C$43<>""),--(MMULT(--('כיתה ו4'!$F$7:$AE$43<>""),TRANSPOSE(COLUMN('כיתה ו4'!$F$7:$AE$7)^0))>0))+SUMPRODUCT('כיתה ו5'!$AF$7:$AF$43,--('כיתה ו5'!$C$7:$C$43<>""),--(MMULT(--('כיתה ו5'!$F$7:$AE$43<>""),TRANSPOSE(COLUMN('כיתה ו5'!$F$7:$AE$7)^0))>0)))/((COUNTA('כיתה ו1'!$C$7:$C$43)-SUMPRODUCT(--('כיתה ו1'!$C$7:$C$43<>""),--(MMULT(--('כיתה ו1'!$F$7:$AE$43<>""),TRANSPOSE(COLUMN('כיתה ו1'!$F$7:$AE$7)^0))=0)))+(COUNTA('כיתה ו2'!$C$7:$C$43)-SUMPRODUCT(--('כיתה ו2'!$C$7:$C$43<>""),--(MMULT(--('כיתה ו2'!$F$7:$AE$43<>""),TRANSPOSE(COLUMN('כיתה ו2'!$F$7:$AE$7)^0))=0)))+(COUNTA('כיתה ו3'!$C$7:$C$43)-SUMPRODUCT(--('כיתה ו3'!$C$7:$C$43<>""),--(MMULT(--('כיתה ו3'!$F$7:$AE$43<>""),TRANSPOSE(COLUMN('כיתה ו3'!$F$7:$AE$7)^0))=0)))+(COUNTA('כיתה ו4'!$C$7:$C$43)-SUMPRODUCT(--('כיתה ו4'!$C$7:$C$43<>""),--(MMULT(--('כיתה ו4'!$F$7:$AE$43<>""),TRANSPOSE(COLUMN('כיתה ו4'!$F$7:$AE$7)^0))=0)))+(COUNTA('כיתה ו5'!$C$7:$C$43)-SUMPRODUCT(--('כיתה ו5'!$C$7:$C$43<>""),--(MMULT(--('כיתה ו5'!$F$7:$AE$43<>""),TRANSPOSE(COLUMN('כיתה ו5'!$F$7:$AE$7)^0))=0)))),0)} -> 0 | C14: {=SUMPRODUCT(--('כיתה ו1'!$C$7:$C$43<>""),--('כיתה ו1'!$AF$7:$AF$43>=86),--('כיתה ו1'!$AF$7:$AF$43<=100),--(MMULT(--('כיתה ו1'!$F$7:$AE$43<>""),TRANSPOSE(COLUMN('כיתה ו1'!$F$7:$AE$7)^0))>0))+SUMPRODUCT(--('כיתה ו2'!$C$7:$C$43<>""),--('כיתה ו2'!$AF$7:$AF$43>=86),--('כיתה ו2'!$AF$7:$AF$43<=100),--(MMULT(--('כיתה ו2'!$F$7:$AE$43<>""),TRANSPOSE(COLUMN('כיתה ו2'!$F$7:$AE$7)^0))>0))+SUMPRODUCT(--('כיתה ו3'!$C$7:$C$43<>""),--('כיתה ו3'!$AF$7:$AF$43>=86),--('כיתה ו3'!$AF$7:$AF$43<=100),--(MMULT(--('כיתה ו3'!$F$7:$AE$43<>""),TRANSPOSE(COLUMN('כיתה ו3'!$F$7:$AE$7)^0))>0))+SUMPRODUCT(--('כיתה ו4'!$C$7:$C$43<>""),--('כיתה ו4'!$AF$7:$AF$43>=86),--('כיתה ו4'!$AF$7:$AF$43<=100),--(MMULT(--('כיתה ו4'!$F$7:$AE$43<>""),TRANSPOSE(COLUMN('כיתה ו4'!$F$7:$AE$7)^0))>0))+SUMPRODUCT(--('כיתה ו5'!$C$7:$C$43<>""),--('כיתה ו5'!$AF$7:$AF$43>=86),--('כיתה ו5'!$AF$7:$AF$43<=100),--(MMULT(--('כיתה ו5'!$F$7:$AE$43<>""),TRANSPOSE(COLUMN('כיתה ו5'!$F$7:$AE$7)^0))>0))} -> 0 | D14: {=SUMPRODUCT(--('כיתה ו1'!$C$7:$C$43<>""),--('כיתה ו1'!$AF$7:$AF$43>=70),--('כיתה ו1'!$AF$7:$AF$43<=85),--(MMULT(--('כיתה ו1'!$F$7:$AE$43<>""),TRANSPOSE(COLUMN('כיתה ו1'!$F$7:$AE$7)^0))>0))+SUMPRODUCT(--('כיתה ו2'!$C$7:$C$43<>""),--('כיתה ו2'!$AF$7:$AF$43>=70),--('כיתה ו2'!$AF$7:$AF$43<=85),--(MMULT(--('כיתה ו2'!$F$7:$AE$43<>""),TRANSPOSE(COLUMN('כיתה ו2'!$F$7:$AE$7)^0))>0))+SUMPRODUCT(--('כיתה ו3'!$C$7:$C$43<>""),--('כיתה ו3'!$AF$7:$AF$43>=70),--('כיתה ו3'!$AF$7:$AF$43<=85),--(MMULT(--('כיתה ו3'!$F$7:$AE$43<>""),TRANSPOSE(COLUMN('כיתה ו3'!$F$7:$AE$7)^0))>0))+SUMPRODUCT(--('כיתה ו4'!$C$7:$C$43<>""),--('כיתה ו4'!$AF$7:$AF$43>=70),--('כיתה ו4'!$AF$7:$AF$43<=85),--(MMULT(--('כיתה ו4'!$F$7:$AE$43<>""),TRANSPOSE(COLUMN('כיתה ו4'!$F$7:$AE$7)^0))>0))+SUMPRODUCT(--('כיתה ו5'!$C$7:$C$43<>""),--('כיתה ו5'!$AF$7:$AF$43>=70),--('כיתה ו5'!$AF$7:$AF$43<=85),--(MMULT(--('כיתה ו5'!$F$7:$AE$43<>""),TRANSPOSE(COLUMN('כיתה ו5'!$F$7:$AE$7)^0))>0))} -> 0 | E14: {=SUMPRODUCT(--('כיתה ו1'!$C$7:$C$43<>""),--('כיתה ו1'!$AF$7:$AF$43>=55),--('כיתה ו1'!$AF$7:$AF$43<=69),--(MMULT(--('כיתה ו1'!$F$7:$AE$43<>""),TRANSPOSE(COLUMN('כיתה ו1'!$F$7:$AE$7)^0))>0))+SUMPRODUCT(--('כיתה ו2'!$C$7:$C$43<>""),--('כיתה ו2'!$AF$7:$AF$43>=55),--('כיתה ו2'!$AF$7:$AF$43<=69),--(MMULT(--('כיתה ו2'!$F$7:$AE$43<>""),TRANSPOSE(COLUMN('כיתה ו2'!$F$7:$AE$7)^0))>0))+SUMPRODUCT(--('כיתה ו3'!$C$7:$C$43<>""),--('כיתה ו3'!$AF$7:$AF$43>=55),--('כיתה ו3'!$AF$7:$AF$43<=69),--(MMULT(--('כיתה ו3'!$F$7:$AE$43<>""),TRANSPOSE(COLUMN('כיתה ו3'!$F$7:$AE$7)^0))>0))+SUMPRODUCT(--('כיתה ו4'!$C$7:$C$43<>""),--('כיתה ו4'!$AF$7:$AF$43>=55),--('כיתה ו4'!$AF$7:$AF$43<=69),--(MMULT(--('כיתה ו4'!$F$7:$AE$43<>""),TRANSPOSE(COLUMN('כיתה ו4'!$F$7:$AE$7)^0))>0))+SUMPRODUCT(--('כיתה ו5'!$C$7:$C$43<>""),--('כיתה ו5'!$AF$7:$AF$43>=55),--('כיתה ו5'!$AF$7:$AF$43<=69),--(MMULT(--('כיתה ו5'!$F$7:$AE$43<>""),TRANSPOSE(COLUMN('כיתה ו5'!$F$7:$AE$7)^0))>0))} -> 0 | F14: {=SUMPRODUCT(--('כיתה ו1'!$C$7:$C$43<>""),--('כיתה ו1'!$AF$7:$AF$43>=0),--('כיתה ו1'!$AF$7:$AF$43<=54),--(MMULT(--('כיתה ו1'!$F$7:$AE$43<>""),TRANSPOSE(COLUMN('כיתה ו1'!$F$7:$AE$7)^0))>0))+SUMPRODUCT(--('כיתה ו2'!$C$7:$C$43<>""),--('כיתה ו2'!$AF$7:$AF$43>=0),--('כיתה ו2'!$AF$7:$AF$43<=54),--(MMULT(--('כיתה ו2'!$F$7:$AE$43<>""),TRANSPOSE(COLUMN('כיתה ו2'!$F$7:$AE$7)^0))>0))+SUMPRODUCT(--('כיתה ו3'!$C$7:$C$43<>""),--('כיתה ו3'!$AF$7:$AF$43>=0),--('כיתה ו3'!$AF$7:$AF$43<=54),--(MMULT(--('כיתה ו3'!$F$7:$AE$43<>""),TRANSPOSE(COLUMN('כיתה ו3'!$F$7:$AE$7)^0))>0))+SUMPRODUCT(--('כיתה ו4'!$C$7:$C$43<>""),--('כיתה ו4'!$AF$7:$AF$43>=0),--('כיתה ו4'!$AF$7:$AF$43<=54),--(MMULT(--('כיתה ו4'!$F$7:$AE$43<>""),TRANSPOSE(COLUMN('כיתה ו4'!$F$7:$AE$7)^0))>0))+SUMPRODUCT(--('כיתה ו5'!$C$7:$C$43<>""),--('כיתה ו5'!$AF$7:$AF$43>=0),--('כיתה ו5'!$AF$7:$AF$43<=54),--(MMULT(--('כיתה ו5'!$F$7:$AE$43<>""),TRANSPOSE(COLUMN('כיתה ו5'!$F$7:$AE$7)^0))>0))} -> 0 | G14: {=((COUNTA('כיתה ו1'!$C$7:$C$43)-SUMPRODUCT(--('כיתה ו1'!$C$7:$C$43<>""),--(MMULT(--('כיתה ו1'!$F$7:$AE$43<>""),TRANSPOSE(COLUMN('כיתה ו1'!$F$7:$AE$7)^0))=0)))+(COUNTA('כיתה ו2'!$C$7:$C$43)-SUMPRODUCT(--('כיתה ו2'!$C$7:$C$43<>""),--(MMULT(--('כיתה ו2'!$F$7:$AE$43<>""),TRANSPOSE(COLUMN('כיתה ו2'!$F$7:$AE$7)^0))=0)))+(COUNTA('כיתה ו3'!$C$7:$C$43)-SUMPRODUCT(--('כיתה ו3'!$C$7:$C$43<>""),--(MMULT(--('כיתה ו3'!$F$7:$AE$43<>""),TRANSPOSE(COLUMN('כיתה ו3'!$F$7:$AE$7)^0))=0)))+(COUNTA('כיתה ו4'!$C$7:$C$43)-SUMPRODUCT(--('כיתה ו4'!$C$7:$C$43<>""),--(MMULT(--('כיתה ו4'!$F$7:$AE$43<>""),TRANSPOSE(COLUMN('כיתה ו4'!$F$7:$AE$7)^0))=0)))+(COUNTA('כיתה ו5'!$C$7:$C$43)-SUMPRODUCT(--('כיתה ו5'!$C$7:$C$43<>""),--(MMULT(--('כיתה ו5'!$F$7:$AE$43<>""),TRANSPOSE(COLUMN('כיתה ו5'!$F$7:$AE$7)^0))=0))))} -> 0
A17: נושא | B17: ו1 | C17: ו2 | D17: ו3 | E17: ו4 | F17: ו5 | G17: שכבה
A18: מבנה עשרוני | B18: {=IFERROR((SUMIF('כיתה ו1'!$C$7:$C$43,"<>",'כיתה ו1'!$F$7:$F$43))/((COUNTA('כיתה ו1'!$C$7:$C$43)-SUMPRODUCT(--('כיתה ו1'!$C$7:$C$43<>""),--(MMULT(--('כיתה ו1'!$F$7:$AE$43<>""),TRANSPOSE(COLUMN('כיתה ו1'!$F$7:$AE$7)^0))=0)))*4),0)} -> 0 | C18: {=IFERROR((SUMIF('כיתה ו2'!$C$7:$C$43,"<>",'כיתה ו2'!$F$7:$F$43))/((COUNTA('כיתה ו2'!$C$7:$C$43)-SUMPRODUCT(--('כיתה ו2'!$C$7:$C$43<>""),--(MMULT(--('כיתה ו2'!$F$7:$AE$43<>""),TRANSPOSE(COLUMN('כיתה ו2'!$F$7:$AE$7)^0))=0)))*4),0)} -> 0 | D18: {=IFERROR((SUMIF('כיתה ו3'!$C$7:$C$43,"<>",'כיתה ו3'!$F$7:$F$43))/((COUNTA('כיתה ו3'!$C$7:$C$43)-SUMPRODUCT(--('כיתה ו3'!$C$7:$C$43<>""),--(MMULT(--('כיתה ו3'!$F$7:$AE$43<>""),TRANSPOSE(COLUMN('כיתה ו3'!$F$7:$AE$7)^0))=0)))*4),0)} -> 0 | E18: {=IFERROR((SUMIF('כיתה ו4'!$C$7:$C$43,"<>",'כיתה ו4'!$F$7:$F$43))/((COUNTA('כיתה ו4'!$C$7:$C$43)-SUMPRODUCT(--('כיתה ו4'!$C$7:$C$43<>""),--(MMULT(--('כיתה ו4'!$F$7:$AE$43<>""),TRANSPOSE(COLUMN('כיתה ו4'!$F$7:$AE$7)^0))=0)))*4),0)} -> 0 | F18: {=IFERROR((SUMIF('כיתה ו5'!$C$7:$C$43,"<>",'כיתה ו5'!$F$7:$F$43))/((COUNTA('כיתה ו5'!$C$7:$C$43)-SUMPRODUCT(--('כיתה ו5'!$C$7:$C$43<>""),--(MMULT(--('כיתה ו5'!$F$7:$AE$43<>""),TRANSPOSE(COLUMN('כיתה ו5'!$F$7:$AE$7)^0))=0)))*4),0)} -> 0 | G18: {=IFERROR((SUMIF('כיתה ו1'!$C$7:$C$43,"<>",'כיתה ו1'!$F$7:$F$43)+SUMIF('כיתה ו2'!$C$7:$C$43,"<>",'כיתה ו2'!$F$7:$F$43)+SUMIF('כיתה ו3'!$C$7:$C$43,"<>",'כיתה ו3'!$F$7:$F$43)+SUMIF('כיתה ו4'!$C$7:$C$43,"<>",'כיתה ו4'!$F$7:$F$43)+SUMIF('כיתה ו5'!$C$7:$C$43,"<>",'כיתה ו5'!$F$7:$F$43))/(((COUNTA('כיתה ו1'!$C$7:$C$43)-SUMPRODUCT(--('כיתה ו1'!$C$7:$C$43<>""),--(MMULT(--('כיתה ו1'!$F$7:$AE$43<>""),TRANSPOSE(COLUMN('כיתה ו1'!$F$7:$AE$7)^0))=0)))+(COUNTA('כיתה ו2'!$C$7:$C$43)-SUMPRODUCT(--('כיתה ו2'!$C$7:$C$43<>""),--(MMULT(--('כיתה ו2'!$F$7:$AE$43<>""),TRANSPOSE(COLUMN('כיתה ו2'!$F$7:$AE$7)^0))=0)))+(COUNTA('כיתה ו3'!$C$7:$C$43)-SUMPRODUCT(--('כיתה ו3'!$C$7:$C$43<>""),--(MMULT(--('כיתה ו3'!$F$7:$AE$43<>""),TRANSPOSE(COLUMN('כיתה ו3'!$F$7:$AE$7)^0))=0)))+(COUNTA('כיתה ו4'!$C$7:$C$43)-SUMPRODUCT(--('כיתה ו4'!$C$7:$C$43<>""),--(MMULT(--('כיתה ו4'!$F$7:$AE$43<>""),TRANSPOSE(COLUMN('כיתה ו4'!$F$7:$AE$7)^0))=0)))+(COUNTA('כיתה ו5'!$C$7:$C$43)-SUMPRODUCT(--('כיתה ו5'!$C$7:$C$43<>""),--(MMULT(--('כיתה ו5'!$F$7:$AE$43<>""),TRANSPOSE(COLUMN('כיתה ו5'!$F$7:$AE$7)^0))=0))))*4),0)} -> 0
A19: פעולות בשלמים | B19: {=IFERROR((SUMIF('כיתה ו1'!$C$7:$C$43,"<>",'כיתה ו1'!$G$7:$G$43)+SUMIF('כיתה ו1'!$C$7:$C$43,"<>",'כיתה ו1'!$H$7:$H$43)+SUMIF('כיתה ו1'!$C$7:$C$43,"<>",'כיתה ו1'!$I$7:$I$43)+SUMIF('כיתה ו1'!$C$7:$C$43,"<>",'כיתה ו1'!$J$7:$J$43)+SUMIF('כיתה ו1'!$C$7:$C$43,"<>",'כיתה ו1'!$K$7:$K$43)+SUMIF('כיתה ו1'!$C$7:$C$43,"<>",'כיתה ו1'!$L$7:$L$43)+SUMIF('כיתה ו1'!$C$7:$C$43,"<>",'כיתה ו1'!$M$7:$M$43))/((COUNTA('כיתה ו1'!$C$7:$C$43)-SUMPRODUCT(--('כיתה ו1'!$C$7:$C$43<>""),--(MMULT(--('כיתה ו1'!$F$7:$AE$43<>""),TRANSPOSE(COLUMN('כיתה ו1'!$F$7:$AE$7)^0))=0)))*30),0)} -> 0 | C19: {=IFERROR((SUMIF('כיתה ו2'!$C$7:$C$43,"<>",'כיתה ו2'!$G$7:$G$43)+SUMIF('כיתה ו2'!$C$7:$C$43,"<>",'כיתה ו2'!$H$7:$H$43)+SUMIF('כיתה ו2'!$C$7:$C$43,"<>",'כיתה ו2'!$I$7:$I$43)+SUMIF('כיתה ו2'!$C$7:$C$43,"<>",'כיתה ו2'!$J$7:$J$43)+SUMIF('כיתה ו2'!$C$7:$C$43,"<>",'כיתה ו2'!$K$7:$K$43)+SUMIF('כיתה ו2'!$C$7:$C$43,"<>",'כיתה ו2'!$L$7:$L$43)+SUMIF('כיתה ו2'!$C$7:$C$43,"<>",'כיתה ו2'!$M$7:$M$43))/((COUNTA('כיתה ו2'!$C$7:$C$43)-SUMPRODUCT(--('כיתה ו2'!$C$7:$C$43<>""),--(MMULT(--('כיתה ו2'!$F$7:$AE$43<>""),TRANSPOSE(COLUMN('כיתה ו2'!$F$7:$AE$7)^0))=0)))*30),0)} -> 0 | D19: {=IFERROR((SUMIF('כיתה ו3'!$C$7:$C$43,"<>",'כיתה ו3'!$G$7:$G$43)+SUMIF('כיתה ו3'!$C$7:$C$43,"<>",'כיתה ו3'!$H$7:$H$43)+SUMIF('כיתה ו3'!$C$7:$C$43,"<>",'כיתה ו3'!$I$7:$I$43)+SUMIF('כיתה ו3'!$C$7:$C$43,"<>",'כיתה ו3'!$J$7:$J$43)+SUMIF('כיתה ו3'!$C$7:$C$43,"<>",'כיתה ו3'!$K$7:$K$43)+SUMIF('כיתה ו3'!$C$7:$C$43,"<>",'כיתה ו3'!$L$7:$L$43)+SUMIF('כיתה ו3'!$C$7:$C$43,"<>",'כיתה ו3'!$M$7:$M$43))/((COUNTA('כיתה ו3'!$C$7:$C$43)-SUMPRODUCT(--('כיתה ו3'!$C$7:$C$43<>""),--(MMULT(--('כיתה ו3'!$F$7:$AE$43<>""),TRANSPOSE(COLUMN('כיתה ו3'!$F$7:$AE$7)^0))=0)))*30),0)} -> 0 | E19: {=IFERROR((SUMIF('כיתה ו4'!$C$7:$C$43,"<>",'כיתה ו4'!$G$7:$G$43)+SUMIF('כיתה ו4'!$C$7:$C$43,"<>",'כיתה ו4'!$H$7:$H$43)+SUMIF('כיתה ו4'!$C$7:$C$43,"<>",'כיתה ו4'!$I$7:$I$43)+SUMIF('כיתה ו4'!$C$7:$C$43,"<>",'כיתה ו4'!$J$7:$J$43)+SUMIF('כיתה ו4'!$C$7:$C$43,"<>",'כיתה ו4'!$K$7:$K$43)+SUMIF('כיתה ו4'!$C$7:$C$43,"<>",'כיתה ו4'!$L$7:$L$43)+SUMIF('כיתה ו4'!$C$7:$C$43,"<>",'כיתה ו4'!$M$7:$M$43))/((COUNTA('כיתה ו4'!$C$7:$C$43)-SUMPRODUCT(--('כיתה ו4'!$C$7:$C$43<>""),--(MMULT(--('כיתה ו4'!$F$7:$AE$43<>""),TRANSPOSE(COLUMN('כיתה ו4'!$F$7:$AE$7)^0))=0)))*30),0)} -> 0 | F19: {=IFERROR((SUMIF('כיתה ו5'!$C$7:$C$43,"<>",'כיתה ו5'!$G$7:$G$43)+SUMIF('כיתה ו5'!$C$7:$C$43,"<>",'כיתה ו5'!$H$7:$H$43)+SUMIF('כיתה ו5'!$C$7:$C$43,"<>",'כיתה ו5'!$I$7:$I$43)+SUMIF('כיתה ו5'!$C$7:$C$43,"<>",'כיתה ו5'!$J$7:$J$43)+SUMIF('כיתה ו5'!$C$7:$C$43,"<>",'כיתה ו5'!$K$7:$K$43)+SUMIF('כיתה ו5'!$C$7:$C$43,"<>",'כיתה ו5'!$L$7:$L$43)+SUMIF('כיתה ו5'!$C$7:$C$43,"<>",'כיתה ו5'!$M$7:$M$43))/((COUNTA('כיתה ו5'!$C$7:$C$43)-SUMPRODUCT(--('כיתה ו5'!$C$7:$C$43<>""),--(MMULT(--('כיתה ו5'!$F$7:$AE$43<>""),TRANSPOSE(COLUMN('כיתה ו5'!$F$7:$AE$7)^0))=0)))*30),0)} -> 0 | G19: {=IFERROR((SUMIF('כיתה ו1'!$C$7:$C$43,"<>",'כיתה ו1'!$G$7:$G$43)+SUMIF('כיתה ו1'!$C$7:$C$43,"<>",'כיתה ו1'!$H$7:$H$43)+SUMIF('כיתה ו1'!$C$7:$C$43,"<>",'כיתה ו1'!$I$7:$I$43)+SUMIF('כיתה ו1'!$C$7:$C$43,"<>",'כיתה ו1'!$J$7:$J$43)+SUMIF('כיתה ו1'!$C$7:$C$43,"<>",'כיתה ו1'!$K$7:$K$43)+SUMIF('כיתה ו1'!$C$7:$C$43,"<>",'כיתה ו1'!$L$7:$L$43)+SUMIF('כיתה ו1'!$C$7:$C$43,"<>",'כיתה ו1'!$M$7:$M$43)+SUMIF('כיתה ו2'!$C$7:$C$43,"<>",'כיתה ו2'!$G$7:$G$43)+SUMIF('כיתה ו2'!$C$7:$C$43,"<>",'כיתה ו2'!$H$7:$H$43)+SUMIF('כיתה ו2'!$C$7:$C$43,"<>",'כיתה ו2'!$I$7:$I$43)+SUMIF('כיתה ו2'!$C$7:$C$43,"<>",'כיתה ו2'!$J$7:$J$43)+SUMIF('כיתה ו2'!$C$7:$C$43,"<>",'כיתה ו2'!$K$7:$K$43)+SUMIF('כיתה ו2'!$C$7:$C$43,"<>",'כיתה ו2'!$L$7:$L$43)+SUMIF('כיתה ו2'!$C$7:$C$43,"<>",'כיתה ו2'!$M$7:$M$43)+SUMIF('כיתה ו3'!$C$7:$C$43,"<>",'כיתה ו3'!$G$7:$G$43)+SUMIF('כיתה ו3'!$C$7:$C$43,"<>",'כיתה ו3'!$H$7:$H$43)+SUMIF('כיתה ו3'!$C$7:$C$43,"<>",'כיתה ו3'!$I$7:$I$43)+SUMIF('כיתה ו3'!$C$7:$C$43,"<>",'כיתה ו3'!$J$7:$J$43)+SUMIF('כיתה ו3'!$C$7:$C$43,"<>",'כיתה ו3'!$K$7:$K$43)+SUMIF('כיתה ו3'!$C$7:$C$43,"<>",'כיתה ו3'!$L$7:$L$43)+SUMIF('כיתה ו3'!$C$7:$C$43,"<>",'כיתה ו3'!$M$7:$M$43)+SUMIF('כיתה ו4'!$C$7:$C$43,"<>",'כיתה ו4'!$G$7:$G$43)+SUMIF('כיתה ו4'!$C$7:$C$43,"<>",'כיתה ו4'!$H$7:$H$43)+SUMIF('כיתה ו4'!$C$7:$C$43,"<>",'כיתה ו4'!$I$7:$I$43)+SUMIF('כיתה ו4'!$C$7:$C$43,"<>",'כיתה ו4'!$J$7:$J$43)+SUMIF('כיתה ו4'!$C$7:$C$43,"<>",'כיתה ו4'!$K$7:$K$43)+SUMIF('כיתה ו4'!$C$7:$C$43,"<>",'כיתה ו4'!$L$7:$L$43)+SUMIF('כיתה ו4'!$C$7:$C$43,"<>",'כיתה ו4'!$M$7:$M$43)+SUMIF('כיתה ו5'!$C$7:$C$43,"<>",'כיתה ו5'!$G$7:$G$43)+SUMIF('כיתה ו5'!$C$7:$C$43,"<>",'כיתה ו5'!$H$7:$H$43)+SUMIF('כיתה ו5'!$C$7:$C$43,"<>",'כיתה ו5'!$I$7:$I$43)+SUMIF('כיתה ו5'!$C$7:$C$43,"<>",'כיתה ו5'!$J$7:$J$43)+SUMIF('כיתה ו5'!$C$7:$C$43,"<>",'כיתה ו5'!$K$7:$K$43)+SUMIF('כיתה ו5'!$C$7:$C$43,"<>",'כיתה ו5'!$L$7:$L$43)+SUMIF('כיתה ו5'!$C$7:$C$43,"<>",'כיתה ו5'!$M$7:$M$43))/(((COUNTA('כיתה ו1'!$C$7:$C$43)-SUMPRODUCT(--('כיתה ו1'!$C$7:$C$43<>""),--(MMULT(--('כיתה ו1'!$F$7:$AE$43<>""),TRANSPOSE(COLUMN('כיתה ו1'!$F$7:$AE$7)^0))=0)))+(COUNTA('כיתה ו2'!$C$7:$C$43)-SUMPRODUCT(--('כיתה ו2'!$C$7:$C$43<>""),--(MMULT(--('כיתה ו2'!$F$7:$AE$43<>""),TRANSPOSE(COLUMN('כיתה ו2'!$F$7:$AE$7)^0))=0)))+(COUNTA('כיתה ו3'!$C$7:$C$43)-SUMPRODUCT(--('כיתה ו3'!$C$7:$C$43<>""),--(MMULT(--('כיתה ו3'!$F$7:$AE$43<>""),TRANSPOSE(COLUMN('כיתה ו3'!$F$7:$AE$7)^0))=0)))+(COUNTA('כיתה ו4'!$C$7:$C$43)-SUMPRODUCT(--('כיתה ו4'!$C$7:$C$43<>""),--(MMULT(--('כיתה ו4'!$F$7:$AE$43<>""),TRANSPOSE(COLUMN('כיתה ו4'!$F$7:$AE$7)^0))=0)))+(COUNTA('כיתה ו5'!$C$7:$C$43)-SUMPRODUCT(--('כיתה ו5'!$C$7:$C$43<>""),--(MMULT(--('כיתה ו5'!$F$7:$AE$43<>""),TRANSPOSE(COLUMN('כיתה ו5'!$F$7:$AE$7)^0))=0))))*30),0)} -> 0
A20: פעולות בשברים | B20: {=IFERROR((SUMIF('כיתה ו1'!$C$7:$C$43,"<>",'כיתה ו1'!$N$7:$N$43)+SUMIF('כיתה ו1'!$C$7:$C$43,"<>",'כיתה ו1'!$O$7:$O$43)+SUMIF('כיתה ו1'!$C$7:$C$43,"<>",'כיתה ו1'!$P$7:$P$43)+SUMIF('כיתה ו1'!$C$7:$C$43,"<>",'כיתה ו1'!$Q$7:$Q$43)+SUMIF('כיתה ו1'!$C$7:$C$43,"<>",'כיתה ו1'!$AA$7:$AA$43))/((COUNTA('כיתה ו1'!$C$7:$C$43)-SUMPRODUCT(--('כיתה ו1'!$C$7:$C$43<>""),--(MMULT(--('כיתה ו1'!$F$7:$AE$43<>""),TRANSPOSE(COLUMN('כיתה ו1'!$F$7:$AE$7)^0))=0)))*20),0)} -> 0 | C20: {=IFERROR((SUMIF('כיתה ו2'!$C$7:$C$43,"<>",'כיתה ו2'!$N$7:$N$43)+SUMIF('כיתה ו2'!$C$7:$C$43,"<>",'כיתה ו2'!$O$7:$O$43)+SUMIF('כיתה ו2'!$C$7:$C$43,"<>",'כיתה ו2'!$P$7:$P$43)+SUMIF('כיתה ו2'!$C$7:$C$43,"<>",'כיתה ו2'!$Q$7:$Q$43)+SUMIF('כיתה ו2'!$C$7:$C$43,"<>",'כיתה ו2'!$AA$7:$AA$43))/((COUNTA('כיתה ו2'!$C$7:$C$43)-SUMPRODUCT(--('כיתה ו2'!$C$7:$C$43<>""),--(MMULT(--('כיתה ו2'!$F$7:$AE$43<>""),TRANSPOSE(COLUMN('כיתה ו2'!$F$7:$AE$7)^0))=0)))*20),0)} -> 0 | D20: {=IFERROR((SUMIF('כיתה ו3'!$C$7:$C$43,"<>",'כיתה ו3'!$N$7:$N$43)+SUMIF('כיתה ו3'!$C$7:$C$43,"<>",'כיתה ו3'!$O$7:$O$43)+SUMIF('כיתה ו3'!$C$7:$C$43,"<>",'כיתה ו3'!$P$7:$P$43)+SUMIF('כיתה ו3'!$C$7:$C$43,"<>",'כיתה ו3'!$Q$7:$Q$43)+SUMIF('כיתה ו3'!$C$7:$C$43,"<>",'כיתה ו3'!$AA$7:$AA$43))/((COUNTA('כיתה ו3'!$C$7:$C$43)-SUMPRODUCT(--('כיתה ו3'!$C$7:$C$43<>""),--(MMULT(--('כיתה ו3'!$F$7:$AE$43<>""),TRANSPOSE(COLUMN('כיתה ו3'!$F$7:$AE$7)^0))=0)))*20),0)} -> 0 | E20: {=IFERROR((SUMIF('כיתה ו4'!$C$7:$C$43,"<>",'כיתה ו4'!$N$7:$N$43)+SUMIF('כיתה ו4'!$C$7:$C$43,"<>",'כיתה ו4'!$O$7:$O$43)+SUMIF('כיתה ו4'!$C$7:$C$43,"<>",'כיתה ו4'!$P$7:$P$43)+SUMIF('כיתה ו4'!$C$7:$C$43,"<>",'כיתה ו4'!$Q$7:$Q$43)+SUMIF('כיתה ו4'!$C$7:$C$43,"<>",'כיתה ו4'!$AA$7:$AA$43))/((COUNTA('כיתה ו4'!$C$7:$C$43)-SUMPRODUCT(--('כיתה ו4'!$C$7:$C$43<>""),--(MMULT(--('כיתה ו4'!$F$7:$AE$43<>""),TRANSPOSE(COLUMN('כיתה ו4'!$F$7:$AE$7)^0))=0)))*20),0)} -> 0 | F20: {=IFERROR((SUMIF('כיתה ו5'!$C$7:$C$43,"<>",'כיתה ו5'!$N$7:$N$43)+SUMIF('כיתה ו5'!$C$7:$C$43,"<>",'כיתה ו5'!$O$7:$O$43)+SUMIF('כיתה ו5'!$C$7:$C$43,"<>",'כיתה ו5'!$P$7:$P$43)+SUMIF('כיתה ו5'!$C$7:$C$43,"<>",'כיתה ו5'!$Q$7:$Q$43)+SUMIF('כיתה ו5'!$C$7:$C$43,"<>",'כיתה ו5'!$AA$7:$AA$43))/((COUNTA('כיתה ו5'!$C$7:$C$43)-SUMPRODUCT(--('כיתה ו5'!$C$7:$C$43<>""),--(MMULT(--('כיתה ו5'!$F$7:$AE$43<>""),TRANSPOSE(COLUMN('כיתה ו5'!$F$7:$AE$7)^0))=0)))*20),0)} -> 0 | G20: {=IFERROR((SUMIF('כיתה ו1'!$C$7:$C$43,"<>",'כיתה ו1'!$N$7:$N$43)+SUMIF('כיתה ו1'!$C$7:$C$43,"<>",'כיתה ו1'!$O$7:$O$43)+SUMIF('כיתה ו1'!$C$7:$C$43,"<>",'כיתה ו1'!$P$7:$P$43)+SUMIF('כיתה ו1'!$C$7:$C$43,"<>",'כיתה ו1'!$Q$7:$Q$43)+SUMIF('כיתה ו1'!$C$7:$C$43,"<>",'כיתה ו1'!$AA$7:$AA$43)+SUMIF('כיתה ו2'!$C$7:$C$43,"<>",'כיתה ו2'!$N$7:$N$43)+SUMIF('כיתה ו2'!$C$7:$C$43,"<>",'כיתה ו2'!$O$7:$O$43)+SUMIF('כיתה ו2'!$C$7:$C$43,"<>",'כיתה ו2'!$P$7:$P$43)+SUMIF('כיתה ו2'!$C$7:$C$43,"<>",'כיתה ו2'!$Q$7:$Q$43)+SUMIF('כיתה ו2'!$C$7:$C$43,"<>",'כיתה ו2'!$AA$7:$AA$43)+SUMIF('כיתה ו3'!$C$7:$C$43,"<>",'כיתה ו3'!$N$7:$N$43)+SUMIF('כיתה ו3'!$C$7:$C$43,"<>",'כיתה ו3'!$O$7:$O$43)+SUMIF('כיתה ו3'!$C$7:$C$43,"<>",'כיתה ו3'!$P$7:$P$43)+SUMIF('כיתה ו3'!$C$7:$C$43,"<>",'כיתה ו3'!$Q$7:$Q$43)+SUMIF('כיתה ו3'!$C$7:$C$43,"<>",'כיתה ו3'!$AA$7:$AA$43)+SUMIF('כיתה ו4'!$C$7:$C$43,"<>",'כיתה ו4'!$N$7:$N$43)+SUMIF('כיתה ו4'!$C$7:$C$43,"<>",'כיתה ו4'!$O$7:$O$43)+SUMIF('כיתה ו4'!$C$7:$C$43,"<>",'כיתה ו4'!$P$7:$P$43)+SUMIF('כיתה ו4'!$C$7:$C$43,"<>",'כיתה ו4'!$Q$7:$Q$43)+SUMIF('כיתה ו4'!$C$7:$C$43,"<>",'כיתה ו4'!$AA$7:$AA$43)+SUMIF('כיתה ו5'!$C$7:$C$43,"<>",'כיתה ו5'!$N$7:$N$43)+SUMIF('כיתה ו5'!$C$7:$C$43,"<>",'כיתה ו5'!$O$7:$O$43)+SUMIF('כיתה ו5'!$C$7:$C$43,"<>",'כיתה ו5'!$P$7:$P$43)+SUMIF('כיתה ו5'!$C$7:$C$43,"<>",'כיתה ו5'!$Q$7:$Q$43)+SUMIF('כיתה ו5'!$C$7:$C$43,"<>",'כיתה ו5'!$AA$7:$AA$43))/(((COUNTA('כיתה ו1'!$C$7:$C$43)-SUMPRODUCT(--('כיתה ו1'!$C$7:$C$43<>""),--(MMULT(--('כיתה ו1'!$F$7:$AE$43<>""),TRANSPOSE(COLUMN('כיתה ו1'!$F$7:$AE$7)^0))=0)))+(COUNTA('כיתה ו2'!$C$7:$C$43)-SUMPRODUCT(--('כיתה ו2'!$C$7:$C$43<>""),--(MMULT(--('כיתה ו2'!$F$7:$AE$43<>""),TRANSPOSE(COLUMN('כיתה ו2'!$F$7:$AE$7)^0))=0)))+(COUNTA('כיתה ו3'!$C$7:$C$43)-SUMPRODUCT(--('כיתה ו3'!$C$7:$C$43<>""),--(MMULT(--('כיתה ו3'!$F$7:$AE$43<>""),TRANSPOSE(COLUMN('כיתה ו3'!$F$7:$AE$7)^0))=0)))+(COUNTA('כיתה ו4'!$C$7:$C$43)-SUMPRODUCT(--('כיתה ו4'!$C$7:$C$43<>""),--(MMULT(--('כיתה ו4'!$F$7:$AE$43<>""),TRANSPOSE(COLUMN('כיתה ו4'!$F$7:$AE$7)^0))=0)))+(COUNTA('כיתה ו5'!$C$7:$C$43)-SUMPRODUCT(--('כיתה ו5'!$C$7:$C$43<>""),--(MMULT(--('כיתה ו5'!$F$7:$AE$43<>""),TRANSPOSE(COLUMN('כיתה ו5'!$F$7:$AE$7)^0))=0))))*20),0)} -> 0
A21: משמעות השבר | B21: {=IFERROR((SUMIF('כיתה ו1'!$C$7:$C$43,"<>",'כיתה ו1'!$R$7:$R$43)+SUMIF('כיתה ו1'!$C$7:$C$43,"<>",'כיתה ו1'!$W$7:$W$43)+SUMIF('כיתה ו1'!$C$7:$C$43,"<>",'כיתה ו1'!$Y$7:$Y$43))/((COUNTA('כיתה ו1'!$C$7:$C$43)-SUMPRODUCT(--('כיתה ו1'!$C$7:$C$43<>""),--(MMULT(--('כיתה ו1'!$F$7:$AE$43<>""),TRANSPOSE(COLUMN('כיתה ו1'!$F$7:$AE$7)^0))=0)))*13),0)} -> 0 | C21: {=IFERROR((SUMIF('כיתה ו2'!$C$7:$C$43,"<>",'כיתה ו2'!$R$7:$R$43)+SUMIF('כיתה ו2'!$C$7:$C$43,"<>",'כיתה ו2'!$W$7:$W$43)+SUMIF('כיתה ו2'!$C$7:$C$43,"<>",'כיתה ו2'!$Y$7:$Y$43))/((COUNTA('כיתה ו2'!$C$7:$C$43)-SUMPRODUCT(--('כיתה ו2'!$C$7:$C$43<>""),--(MMULT(--('כיתה ו2'!$F$7:$AE$43<>""),TRANSPOSE(COLUMN('כיתה ו2'!$F$7:$AE$7)^0))=0)))*13),0)} -> 0 | D21: {=IFERROR((SUMIF('כיתה ו3'!$C$7:$C$43,"<>",'כיתה ו3'!$R$7:$R$43)+SUMIF('כיתה ו3'!$C$7:$C$43,"<>",'כיתה ו3'!$W$7:$W$43)+SUMIF('כיתה ו3'!$C$7:$C$43,"<>",'כיתה ו3'!$Y$7:$Y$43))/((COUNTA('כיתה ו3'!$C$7:$C$43)-SUMPRODUCT(--('כיתה ו3'!$C$7:$C$43<>""),--(MMULT(--('כיתה ו3'!$F$7:$AE$43<>""),TRANSPOSE(COLUMN('כיתה ו3'!$F$7:$AE$7)^0))=0)))*13),0)} -> 0 | E21: {=IFERROR((SUMIF('כיתה ו4'!$C$7:$C$43,"<>",'כיתה ו4'!$R$7:$R$43)+SUMIF('כיתה ו4'!$C$7:$C$43,"<>",'כיתה ו4'!$W$7:$W$43)+SUMIF('כיתה ו4'!$C$7:$C$43,"<>",'כיתה ו4'!$Y$7:$Y$43))/((COUNTA('כיתה ו4'!$C$7:$C$43)-SUMPRODUCT(--('כיתה ו4'!$C$7:$C$43<>""),--(MMULT(--('כיתה ו4'!$F$7:$AE$43<>""),TRANSPOSE(COLUMN('כיתה ו4'!$F$7:$AE$7)^0))=0)))*13),0)} -> 0 | F21: {=IFERROR((SUMIF('כיתה ו5'!$C$7:$C$43,"<>",'כיתה ו5'!$R$7:$R$43)+SUMIF('כיתה ו5'!$C$7:$C$43,"<>",'כיתה ו5'!$W$7:$W$43)+SUMIF('כיתה ו5'!$C$7:$C$43,"<>",'כיתה ו5'!$Y$7:$Y$43))/((COUNTA('כיתה ו5'!$C$7:$C$43)-SUMPRODUCT(--('כיתה ו5'!$C$7:$C$43<>""),--(MMULT(--('כיתה ו5'!$F$7:$AE$43<>""),TRANSPOSE(COLUMN('כיתה ו5'!$F$7:$AE$7)^0))=0)))*13),0)} -> 0 | G21: {=IFERROR((SUMIF('כיתה ו1'!$C$7:$C$43,"<>",'כיתה ו1'!$R$7:$R$43)+SUMIF('כיתה ו1'!$C$7:$C$43,"<>",'כיתה ו1'!$W$7:$W$43)+SUMIF('כיתה ו1'!$C$7:$C$43,"<>",'כיתה ו1'!$Y$7:$Y$43)+SUMIF('כיתה ו2'!$C$7:$C$43,"<>",'כיתה ו2'!$R$7:$R$43)+SUMIF('כיתה ו2'!$C$7:$C$43,"<>",'כיתה ו2'!$W$7:$W$43)+SUMIF('כיתה ו2'!$C$7:$C$43,"<>",'כיתה ו2'!$Y$7:$Y$43)+SUMIF('כיתה ו3'!$C$7:$C$43,"<>",'כיתה ו3'!$R$7:$R$43)+SUMIF('כיתה ו3'!$C$7:$C$43,"<>",'כיתה ו3'!$W$7:$W$43)+SUMIF('כיתה ו3'!$C$7:$C$43,"<>",'כיתה ו3'!$Y$7:$Y$43)+SUMIF('כיתה ו4'!$C$7:$C$43,"<>",'כיתה ו4'!$R$7:$R$43)+SUMIF('כיתה ו4'!$C$7:$C$43,"<>",'כיתה ו4'!$W$7:$W$43)+SUMIF('כיתה ו4'!$C$7:$C$43,"<>",'כיתה ו4'!$Y$7:$Y$43)+SUMIF('כיתה ו5'!$C$7:$C$43,"<>",'כיתה ו5'!$R$7:$R$43)+SUMIF('כיתה ו5'!$C$7:$C$43,"<>",'כיתה ו5'!$W$7:$W$43)+SUMIF('כיתה ו5'!$C$7:$C$43,"<>",'כיתה ו5'!$Y$7:$Y$43))/(((COUNTA('כיתה ו1'!$C$7:$C$43)-SUMPRODUCT(--('כיתה ו1'!$C$7:$C$43<>""),--(MMULT(--('כיתה ו1'!$F$7:$AE$43<>""),TRANSPOSE(COLUMN('כיתה ו1'!$F$7:$AE$7)^0))=0)))+(COUNTA('כיתה ו2'!$C$7:$C$43)-SUMPRODUCT(--('כיתה ו2'!$C$7:$C$43<>""),--(MMULT(--('כיתה ו2'!$F$7:$AE$43<>""),TRANSPOSE(COLUMN('כיתה ו2'!$F$7:$AE$7)^0))=0)))+(COUNTA('כיתה ו3'!$C$7:$C$43)-SUMPRODUCT(--('כיתה ו3'!$C$7:$C$43<>""),--(MMULT(--('כיתה ו3'!$F$7:$AE$43<>""),TRANSPOSE(COLUMN('כיתה ו3'!$F$7:$AE$7)^0))=0)))+(COUNTA('כיתה ו4'!$C$7:$C$43)-SUMPRODUCT(--('כיתה ו4'!$C$7:$C$43<>""),--(MMULT(--('כיתה ו4'!$F$7:$AE$43<>""),TRANSPOSE(COLUMN('כיתה ו4'!$F$7:$AE$7)^0))=0)))+(COUNTA('כיתה ו5'!$C$7:$C$43)-SUMPRODUCT(--('כיתה ו5'!$C$7:$C$43<>""),--(MMULT(--('כיתה ו5'!$F$7:$AE$43<>""),TRANSPOSE(COLUMN('כיתה ו5'!$F$7:$AE$7)^0))=0))))*13),0)} -> 0
A22: חקר נתונים | B22: {=IFERROR((SUMIF('כיתה ו1'!$C$7:$C$43,"<>",'כיתה ו1'!$S$7:$S$43)+SUMIF('כיתה ו1'!$C$7:$C$43,"<>",'כיתה ו1'!$T$7:$T$43)+SUMIF('כיתה ו1'!$C$7:$C$43,"<>",'כיתה ו1'!$U$7:$U$43)+SUMIF('כיתה ו1'!$C$7:$C$43,"<>",'כיתה ו1'!$V$7:$V$43))/((COUNTA('כיתה ו1'!$C$7:$C$43)-SUMPRODUCT(--('כיתה ו1'!$C$7:$C$43<>""),--(MMULT(--('כיתה ו1'!$F$7:$AE$43<>""),TRANSPOSE(COLUMN('כיתה ו1'!$F$7:$AE$7)^0))=0)))*8),0)} -> 0 | C22: {=IFERROR((SUMIF('כיתה ו2'!$C$7:$C$43,"<>",'כיתה ו2'!$S$7:$S$43)+SUMIF('כיתה ו2'!$C$7:$C$43,"<>",'כיתה ו2'!$T$7:$T$43)+SUMIF('כיתה ו2'!$C$7:$C$43,"<>",'כיתה ו2'!$U$7:$U$43)+SUMIF('כיתה ו2'!$C$7:$C$43,"<>",'כיתה ו2'!$V$7:$V$43))/((COUNTA('כיתה ו2'!$C$7:$C$43)-SUMPRODUCT(--('כיתה ו2'!$C$7:$C$43<>""),--(MMULT(--('כיתה ו2'!$F$7:$AE$43<>""),TRANSPOSE(COLUMN('כיתה ו2'!$F$7:$AE$7)^0))=0)))*8),0)} -> 0 | D22: {=IFERROR((SUMIF('כיתה ו3'!$C$7:$C$43,"<>",'כיתה ו3'!$S$7:$S$43)+SUMIF('כיתה ו3'!$C$7:$C$43,"<>",'כיתה ו3'!$T$7:$T$43)+SUMIF('כיתה ו3'!$C$7:$C$43,"<>",'כיתה ו3'!$U$7:$U$43)+SUMIF('כיתה ו3'!$C$7:$C$43,"<>",'כיתה ו3'!$V$7:$V$43))/((COUNTA('כיתה ו3'!$C$7:$C$43)-SUMPRODUCT(--('כיתה ו3'!$C$7:$C$43<>""),--(MMULT(--('כיתה ו3'!$F$7:$AE$43<>""),TRANSPOSE(COLUMN('כיתה ו3'!$F$7:$AE$7)^0))=0)))*8),0)} -> 0 | E22: {=IFERROR((SUMIF('כיתה ו4'!$C$7:$C$43,"<>",'כיתה ו4'!$S$7:$S$43)+SUMIF('כיתה ו4'!$C$7:$C$43,"<>",'כיתה ו4'!$T$7:$T$43)+SUMIF('כיתה ו4'!$C$7:$C$43,"<>",'כיתה ו4'!$U$7:$U$43)+SUMIF('כיתה ו4'!$C$7:$C$43,"<>",'כיתה ו4'!$V$7:$V$43))/((COUNTA('כיתה ו4'!$C$7:$C$43)-SUMPRODUCT(--('כיתה ו4'!$C$7:$C$43<>""),--(MMULT(--('כיתה ו4'!$F$7:$AE$43<>""),TRANSPOSE(COLUMN('כיתה ו4'!$F$7:$AE$7)^0))=0)))*8),0)} -> 0 | F22: {=IFERROR((SUMIF('כיתה ו5'!$C$7:$C$43,"<>",'כיתה ו5'!$S$7:$S$43)+SUMIF('כיתה ו5'!$C$7:$C$43,"<>",'כיתה ו5'!$T$7:$T$43)+SUMIF('כיתה ו5'!$C$7:$C$43,"<>",'כיתה ו5'!$U$7:$U$43)+SUMIF('כיתה ו5'!$C$7:$C$43,"<>",'כיתה ו5'!$V$7:$V$43))/((COUNTA('כיתה ו5'!$C$7:$C$43)-SUMPRODUCT(--('כיתה ו5'!$C$7:$C$43<>""),--(MMULT(--('כיתה ו5'!$F$7:$AE$43<>""),TRANSPOSE(COLUMN('כיתה ו5'!$F$7:$AE$7)^0))=0)))*8),0)} -> 0 | G22: {=IFERROR((SUMIF('כיתה ו1'!$C$7:$C$43,"<>",'כיתה ו1'!$S$7:$S$43)+SUMIF('כיתה ו1'!$C$7:$C$43,"<>",'כיתה ו1'!$T$7:$T$43)+SUMIF('כיתה ו1'!$C$7:$C$43,"<>",'כיתה ו1'!$U$7:$U$43)+SUMIF('כיתה ו1'!$C$7:$C$43,"<>",'כיתה ו1'!$V$7:$V$43)+SUMIF('כיתה ו2'!$C$7:$C$43,"<>",'כיתה ו2'!$S$7:$S$43)+SUMIF('כיתה ו2'!$C$7:$C$43,"<>",'כיתה ו2'!$T$7:$T$43)+SUMIF('כיתה ו2'!$C$7:$C$43,"<>",'כיתה ו2'!$U$7:$U$43)+SUMIF('כיתה ו2'!$C$7:$C$43,"<>",'כיתה ו2'!$V$7:$V$43)+SUMIF('כיתה ו3'!$C$7:$C$43,"<>",'כיתה ו3'!$S$7:$S$43)+SUMIF('כיתה ו3'!$C$7:$C$43,"<>",'כיתה ו3'!$T$7:$T$43)+SUMIF('כיתה ו3'!$C$7:$C$43,"<>",'כיתה ו3'!$U$7:$U$43)+SUMIF('כיתה ו3'!$C$7:$C$43,"<>",'כיתה ו3'!$V$7:$V$43)+SUMIF('כיתה ו4'!$C$7:$C$43,"<>",'כיתה ו4'!$S$7:$S$43)+SUMIF('כיתה ו4'!$C$7:$C$43,"<>",'כיתה ו4'!$T$7:$T$43)+SUMIF('כיתה ו4'!$C$7:$C$43,"<>",'כיתה ו4'!$U$7:$U$43)+SUMIF('כיתה ו4'!$C$7:$C$43,"<>",'כיתה ו4'!$V$7:$V$43)+SUMIF('כיתה ו5'!$C$7:$C$43,"<>",'כיתה ו5'!$S$7:$S$43)+SUMIF('כיתה ו5'!$C$7:$C$43,"<>",'כיתה ו5'!$T$7:$T$43)+SUMIF('כיתה ו5'!$C$7:$C$43,"<>",'כיתה ו5'!$U$7:$U$43)+SUMIF('כיתה ו5'!$C$7:$C$43,"<>",'כיתה ו5'!$V$7:$V$43))/(((COUNTA('כיתה ו1'!$C$7:$C$43)-SUMPRODUCT(--('כיתה ו1'!$C$7:$C$43<>""),--(MMULT(--('כיתה ו1'!$F$7:$AE$43<>""),TRANSPOSE(COLUMN('כיתה ו1'!$F$7:$AE$7)^0))=0)))+(COUNTA('כיתה ו2'!$C$7:$C$43)-SUMPRODUCT(--('כיתה ו2'!$C$7:$C$43<>""),--(MMULT(--('כיתה ו2'!$F$7:$AE$43<>""),TRANSPOSE(COLUMN('כיתה ו2'!$F$7:$AE$7)^0))=0)))+(COUNTA('כיתה ו3'!$C$7:$C$43)-SUMPRODUCT(--('כיתה ו3'!$C$7:$C$43<>""),--(MMULT(--('כיתה ו3'!$F$7:$AE$43<>""),TRANSPOSE(COLUMN('כיתה ו3'!$F$7:$AE$7)^0))=0)))+(COUNTA('כיתה ו4'!$C$7:$C$43)-SUMPRODUCT(--('כיתה ו4'!$C$7:$C$43<>""),--(MMULT(--('כיתה ו4'!$F$7:$AE$43<>""),TRANSPOSE(COLUMN('כיתה ו4'!$F$7:$AE$7)^0))=0)))+(COUNTA('כיתה ו5'!$C$7:$C$43)-SUMPRODUCT(--('כיתה ו5'!$C$7:$C$43<>""),--(MMULT(--('כיתה ו5'!$F$7:$AE$43<>""),TRANSPOSE(COLUMN('כיתה ו5'!$F$7:$AE$7)^0))=0))))*8),0)} -> 0
A23: מספרים עשרוניים | B23: {=IFERROR((SUMIF('כיתה ו1'!$C$7:$C$43,"<>",'כיתה ו1'!$X$7:$X$43)+SUMIF('כיתה ו1'!$C$7:$C$43,"<>",'כיתה ו1'!$Z$7:$Z$43))/((COUNTA('כיתה ו1'!$C$7:$C$43)-SUMPRODUCT(--('כיתה ו1'!$C$7:$C$43<>""),--(MMULT(--('כיתה ו1'!$F$7:$AE$43<>""),TRANSPOSE(COLUMN('כיתה ו1'!$F$7:$AE$7)^0))=0)))*6),0)} -> 0 | C23: {=IFERROR((SUMIF('כיתה ו2'!$C$7:$C$43,"<>",'כיתה ו2'!$X$7:$X$43)+SUMIF('כיתה ו2'!$C$7:$C$43,"<>",'כיתה ו2'!$Z$7:$Z$43))/((COUNTA('כיתה ו2'!$C$7:$C$43)-SUMPRODUCT(--('כיתה ו2'!$C$7:$C$43<>""),--(MMULT(--('כיתה ו2'!$F$7:$AE$43<>""),TRANSPOSE(COLUMN('כיתה ו2'!$F$7:$AE$7)^0))=0)))*6),0)} -> 0 | D23: {=IFERROR((SUMIF('כיתה ו3'!$C$7:$C$43,"<>",'כיתה ו3'!$X$7:$X$43)+SUMIF('כיתה ו3'!$C$7:$C$43,"<>",'כיתה ו3'!$Z$7:$Z$43))/((COUNTA('כיתה ו3'!$C$7:$C$43)-SUMPRODUCT(--('כיתה ו3'!$C$7:$C$43<>""),--(MMULT(--('כיתה ו3'!$F$7:$AE$43<>""),TRANSPOSE(COLUMN('כיתה ו3'!$F$7:$AE$7)^0))=0)))*6),0)} -> 0 | E23: {=IFERROR((SUMIF('כיתה ו4'!$C$7:$C$43,"<>",'כיתה ו4'!$X$7:$X$43)+SUMIF('כיתה ו4'!$C$7:$C$43,"<>",'כיתה ו4'!$Z$7:$Z$43))/((COUNTA('כיתה ו4'!$C$7:$C$43)-SUMPRODUCT(--('כיתה ו4'!$C$7:$C$43<>""),--(MMULT(--('כיתה ו4'!$F$7:$AE$43<>""),TRANSPOSE(COLUMN('כיתה ו4'!$F$7:$AE$7)^0))=0)))*6),0)} -> 0 | F23: {=IFERROR((SUMIF('כיתה ו5'!$C$7:$C$43,"<>",'כיתה ו5'!$X$7:$X$43)+SUMIF('כיתה ו5'!$C$7:$C$43,"<>",'כיתה ו5'!$Z$7:$Z$43))/((COUNTA('כיתה ו5'!$C$7:$C$43)-SUMPRODUCT(--('כיתה ו5'!$C$7:$C$43<>""),--(MMULT(--('כיתה ו5'!$F$7:$AE$43<>""),TRANSPOSE(COLUMN('כיתה ו5'!$F$7:$AE$7)^0))=0)))*6),0)} -> 0 | G23: {=IFERROR((SUMIF('כיתה ו1'!$C$7:$C$43,"<>",'כיתה ו1'!$X$7:$X$43)+SUMIF('כיתה ו1'!$C$7:$C$43,"<>",'כיתה ו1'!$Z$7:$Z$43)+SUMIF('כיתה ו2'!$C$7:$C$43,"<>",'כיתה ו2'!$X$7:$X$43)+SUMIF('כיתה ו2'!$C$7:$C$43,"<>",'כיתה ו2'!$Z$7:$Z$43)+SUMIF('כיתה ו3'!$C$7:$C$43,"<>",'כיתה ו3'!$X$7:$X$43)+SUMIF('כיתה ו3'!$C$7:$C$43,"<>",'כיתה ו3'!$Z$7:$Z$43)+SUMIF('כיתה ו4'!$C$7:$C$43,"<>",'כיתה ו4'!$X$7:$X$43)+SUMIF('כיתה ו4'!$C$7:$C$43,"<>",'כיתה ו4'!$Z$7:$Z$43)+SUMIF('כיתה ו5'!$C$7:$C$43,"<>",'כיתה ו5'!$X$7:$X$43)+SUMIF('כיתה ו5'!$C$7:$C$43,"<>",'כיתה ו5'!$Z$7:$Z$43))/(((COUNTA('כיתה ו1'!$C$7:$C$43)-SUMPRODUCT(--('כיתה ו1'!$C$7:$C$43<>""),--(MMULT(--('כיתה ו1'!$F$7:$AE$43<>""),TRANSPOSE(COLUMN('כיתה ו1'!$F$7:$AE$7)^0))=0)))+(COUNTA('כיתה ו2'!$C$7:$C$43)-SUMPRODUCT(--('כיתה ו2'!$C$7:$C$43<>""),--(MMULT(--('כיתה ו2'!$F$7:$AE$43<>""),TRANSPOSE(COLUMN('כיתה ו2'!$F$7:$AE$7)^0))=0)))+(COUNTA('כיתה ו3'!$C$7:$C$43)-SUMPRODUCT(--('כיתה ו3'!$C$7:$C$43<>""),--(MMULT(--('כיתה ו3'!$F$7:$AE$43<>""),TRANSPOSE(COLUMN('כיתה ו3'!$F$7:$AE$7)^0))=0)))+(COUNTA('כיתה ו4'!$C$7:$C$43)-SUMPRODUCT(--('כיתה ו4'!$C$7:$C$43<>""),--(MMULT(--('כיתה ו4'!$F$7:$AE$43<>""),TRANSPOSE(COLUMN('כיתה ו4'!$F$7:$AE$7)^0))=0)))+(COUNTA('כיתה ו5'!$C$7:$C$43)-SUMPRODUCT(--('כיתה ו5'!$C$7:$C$43<>""),--(MMULT(--('כיתה ו5'!$F$7:$AE$43<>""),TRANSPOSE(COLUMN('כיתה ו5'!$F$7:$AE$7)^0))=0))))*6),0)} -> 0
A24: מצולעים | B24: {=IFERROR((SUMIF('כיתה ו1'!$C$7:$C$43,"<>",'כיתה ו1'!$AB$7:$AB$43)+SUMIF('כיתה ו1'!$C$7:$C$43,"<>",'כיתה ו1'!$AC$7:$AC$43))/((COUNTA('כיתה ו1'!$C$7:$C$43)-SUMPRODUCT(--('כיתה ו1'!$C$7:$C$43<>""),--(MMULT(--('כיתה ו1'!$F$7:$AE$43<>""),TRANSPOSE(COLUMN('כיתה ו1'!$F$7:$AE$7)^0))=0)))*10),0)} -> 0 | C24: {=IFERROR((SUMIF('כיתה ו2'!$C$7:$C$43,"<>",'כיתה ו2'!$AB$7:$AB$43)+SUMIF('כיתה ו2'!$C$7:$C$43,"<>",'כיתה ו2'!$AC$7:$AC$43))/((COUNTA('כיתה ו2'!$C$7:$C$43)-SUMPRODUCT(--('כיתה ו2'!$C$7:$C$43<>""),--(MMULT(--('כיתה ו2'!$F$7:$AE$43<>""),TRANSPOSE(COLUMN('כיתה ו2'!$F$7:$AE$7)^0))=0)))*10),0)} -> 0 | D24: {=IFERROR((SUMIF('כיתה ו3'!$C$7:$C$43,"<>",'כיתה ו3'!$AB$7:$AB$43)+SUMIF('כיתה ו3'!$C$7:$C$43,"<>",'כיתה ו3'!$AC$7:$AC$43))/((COUNTA('כיתה ו3'!$C$7:$C$43)-SUMPRODUCT(--('כיתה ו3'!$C$7:$C$43<>""),--(MMULT(--('כיתה ו3'!$F$7:$AE$43<>""),TRANSPOSE(COLUMN('כיתה ו3'!$F$7:$AE$7)^0))=0)))*10),0)} -> 0 | E24: {=IFERROR((SUMIF('כיתה ו4'!$C$7:$C$43,"<>",'כיתה ו4'!$AB$7:$AB$43)+SUMIF('כיתה ו4'!$C$7:$C$43,"<>",'כיתה ו4'!$AC$7:$AC$43))/((COUNTA('כיתה ו4'!$C$7:$C$43)-SUMPRODUCT(--('כיתה ו4'!$C$7:$C$43<>""),--(MMULT(--('כיתה ו4'!$F$7:$AE$43<>""),TRANSPOSE(COLUMN('כיתה ו4'!$F$7:$AE$7)^0))=0)))*10),0)} -> 0 | F24: {=IFERROR((SUMIF('כיתה ו5'!$C$7:$C$43,"<>",'כיתה ו5'!$AB$7:$AB$43)+SUMIF('כיתה ו5'!$C$7:$C$43,"<>",'כיתה ו5'!$AC$7:$AC$43))/((COUNTA('כיתה ו5'!$C$7:$C$43)-SUMPRODUCT(--('כיתה ו5'!$C$7:$C$43<>""),--(MMULT(--('כיתה ו5'!$F$7:$AE$43<>""),TRANSPOSE(COLUMN('כיתה ו5'!$F$7:$AE$7)^0))=0)))*10),0)} -> 0 | G24: {=IFERROR((SUMIF('כיתה ו1'!$C$7:$C$43,"<>",'כיתה ו1'!$AB$7:$AB$43)+SUMIF('כיתה ו1'!$C$7:$C$43,"<>",'כיתה ו1'!$AC$7:$AC$43)+SUMIF('כיתה ו2'!$C$7:$C$43,"<>",'כיתה ו2'!$AB$7:$AB$43)+SUMIF('כיתה ו2'!$C$7:$C$43,"<>",'כיתה ו2'!$AC$7:$AC$43)+SUMIF('כיתה ו3'!$C$7:$C$43,"<>",'כיתה ו3'!$AB$7:$AB$43)+SUMIF('כיתה ו3'!$C$7:$C$43,"<>",'כיתה ו3'!$AC$7:$AC$43)+SUMIF('כיתה ו4'!$C$7:$C$43,"<>",'כיתה ו4'!$AB$7:$AB$43)+SUMIF('כיתה ו4'!$C$7:$C$43,"<>",'כיתה ו4'!$AC$7:$AC$43)+SUMIF('כיתה ו5'!$C$7:$C$43,"<>",'כיתה ו5'!$AB$7:$AB$43)+SUMIF('כיתה ו5'!$C$7:$C$43,"<>",'כיתה ו5'!$AC$7:$AC$43))/(((COUNTA('כיתה ו1'!$C$7:$C$43)-SUMPRODUCT(--('כיתה ו1'!$C$7:$C$43<>""),--(MMULT(--('כיתה ו1'!$F$7:$AE$43<>""),TRANSPOSE(COLUMN('כיתה ו1'!$F$7:$AE$7)^0))=0)))+(COUNTA('כיתה ו2'!$C$7:$C$43)-SUMPRODUCT(--('כיתה ו2'!$C$7:$C$43<>""),--(MMULT(--('כיתה ו2'!$F$7:$AE$43<>""),TRANSPOSE(COLUMN('כיתה ו2'!$F$7:$AE$7)^0))=0)))+(COUNTA('כיתה ו3'!$C$7:$C$43)-SUMPRODUCT(--('כיתה ו3'!$C$7:$C$43<>""),--(MMULT(--('כיתה ו3'!$F$7:$AE$43<>""),TRANSPOSE(COLUMN('כיתה ו3'!$F$7:$AE$7)^0))=0)))+(COUNTA('כיתה ו4'!$C$7:$C$43)-SUMPRODUCT(--('כיתה ו4'!$C$7:$C$43<>""),--(MMULT(--('כיתה ו4'!$F$7:$AE$43<>""),TRANSPOSE(COLUMN('כיתה ו4'!$F$7:$AE$7)^0))=0)))+(COUNTA('כיתה ו5'!$C$7:$C$43)-SUMPRODUCT(--('כיתה ו5'!$C$7:$C$43<>""),--(MMULT(--('כיתה ו5'!$F$7:$AE$43<>""),TRANSPOSE(COLUMN('כיתה ו5'!$F$7:$AE$7)^0))=0))))*10),0)} -> 0
